2021-03-23 19:26:44,277 (13634/MainThread) pgcli.main INFO - Default pager found in PAGER environment variable: "less"
2021-03-23 19:26:44,277 (13634/MainThread) pgcli.main WARNING - import keyring failed: ModuleNotFoundError("No module named 'keyring'").
2021-03-23 19:26:44,279 (13634/MainThread) pgcli.main ERROR - traceback: 'Traceback (most recent call last):\n  File "/home/rpoole/.pyenv/versions/3.9.1/lib/python3.9/site-packages/pgcli/main.py", line 582, in connect\n    raise e\n  File "/home/rpoole/.pyenv/versions/3.9.1/lib/python3.9/site-packages/pgcli/main.py", line 569, in connect\n    pgexecute = PGExecute(database, user, passwd, host, port, dsn, **kwargs)\n  File "/home/rpoole/.pyenv/versions/3.9.1/lib/python3.9/site-packages/pgcli/pgexecute.py", line 214, in __init__\n    self.connect(database, user, password, host, port, dsn, **kwargs)\n  File "/home/rpoole/.pyenv/versions/3.9.1/lib/python3.9/site-packages/pgcli/pgexecute.py", line 254, in connect\n    conn = psycopg2.connect(**conn_params)\n  File "/home/rpoole/.pyenv/versions/3.9.1/lib/python3.9/site-packages/psycopg2/__init__.py", line 127, in connect\n    conn = _connect(dsn, connection_factory=connection_factory, **kwasync)\n  File "/home/rpoole/.pyenv/versions/3.9.1/lib/python3.9/site-packages/pgcli/pgexecute.py", line 39, in _wait_select\n    state = conn.poll()\npsycopg2.OperationalError: could not connect to server: Connection refused\n\tIs the server running on host "localhost" (127.0.0.1) and accepting\n\tTCP/IP connections on port 5432?\n\n'
2021-03-23 19:27:10,178 (13978/MainThread) pgcli.main INFO - Default pager found in PAGER environment variable: "less"
2021-03-23 19:27:10,178 (13978/MainThread) pgcli.main WARNING - import keyring failed: ModuleNotFoundError("No module named 'keyring'").
2021-03-23 19:27:10,180 (13978/MainThread) pgcli.main ERROR - traceback: 'Traceback (most recent call last):\n  File "/home/rpoole/.pyenv/versions/3.9.1/lib/python3.9/site-packages/pgcli/main.py", line 582, in connect\n    raise e\n  File "/home/rpoole/.pyenv/versions/3.9.1/lib/python3.9/site-packages/pgcli/main.py", line 569, in connect\n    pgexecute = PGExecute(database, user, passwd, host, port, dsn, **kwargs)\n  File "/home/rpoole/.pyenv/versions/3.9.1/lib/python3.9/site-packages/pgcli/pgexecute.py", line 214, in __init__\n    self.connect(database, user, password, host, port, dsn, **kwargs)\n  File "/home/rpoole/.pyenv/versions/3.9.1/lib/python3.9/site-packages/pgcli/pgexecute.py", line 254, in connect\n    conn = psycopg2.connect(**conn_params)\n  File "/home/rpoole/.pyenv/versions/3.9.1/lib/python3.9/site-packages/psycopg2/__init__.py", line 127, in connect\n    conn = _connect(dsn, connection_factory=connection_factory, **kwasync)\npsycopg2.OperationalError: could not connect to server: No such file or directory\n\tIs the server running locally and accepting\n\tconnections on Unix domain socket "/var/run/postgresql/.s.PGSQL.5432"?\n\n'
2021-03-23 19:28:08,954 (15060/MainThread) pgcli.main INFO - Default pager found in PAGER environment variable: "less"
2021-03-23 19:28:08,955 (15060/MainThread) pgcli.main WARNING - import keyring failed: ModuleNotFoundError("No module named 'keyring'").
2021-03-24 17:28:13,571 (15098/MainThread) pgcli.main INFO - Default pager found in PAGER environment variable: "less"
2021-03-24 17:28:13,572 (15098/MainThread) pgcli.main WARNING - import keyring failed: ModuleNotFoundError("No module named 'keyring'").
2021-03-24 17:28:14,795 (15098/MainThread) pgcli.main ERROR - traceback: 'Traceback (most recent call last):\n  File "/home/rpoole/.pyenv/versions/3.9.1/lib/python3.9/site-packages/pgcli/main.py", line 569, in connect\n    pgexecute = PGExecute(database, user, passwd, host, port, dsn, **kwargs)\n  File "/home/rpoole/.pyenv/versions/3.9.1/lib/python3.9/site-packages/pgcli/pgexecute.py", line 214, in __init__\n    self.connect(database, user, password, host, port, dsn, **kwargs)\n  File "/home/rpoole/.pyenv/versions/3.9.1/lib/python3.9/site-packages/pgcli/pgexecute.py", line 254, in connect\n    conn = psycopg2.connect(**conn_params)\n  File "/home/rpoole/.pyenv/versions/3.9.1/lib/python3.9/site-packages/psycopg2/__init__.py", line 127, in connect\n    conn = _connect(dsn, connection_factory=connection_factory, **kwasync)\n  File "/home/rpoole/.pyenv/versions/3.9.1/lib/python3.9/site-packages/pgcli/pgexecute.py", line 39, in _wait_select\n    state = conn.poll()\npsycopg2.OperationalError: fe_sendauth: no password supplied\n\n\nDuring handling of the above exception, another exception occurred:\n\nTraceback (most recent call last):\n  File "/home/rpoole/.pyenv/versions/3.9.1/lib/python3.9/site-packages/pgcli/main.py", line 578, in connect\n    pgexecute = PGExecute(\n  File "/home/rpoole/.pyenv/versions/3.9.1/lib/python3.9/site-packages/pgcli/pgexecute.py", line 214, in __init__\n    self.connect(database, user, password, host, port, dsn, **kwargs)\n  File "/home/rpoole/.pyenv/versions/3.9.1/lib/python3.9/site-packages/pgcli/pgexecute.py", line 254, in connect\n    conn = psycopg2.connect(**conn_params)\n  File "/home/rpoole/.pyenv/versions/3.9.1/lib/python3.9/site-packages/psycopg2/__init__.py", line 127, in connect\n    conn = _connect(dsn, connection_factory=connection_factory, **kwasync)\n  File "/home/rpoole/.pyenv/versions/3.9.1/lib/python3.9/site-packages/pgcli/pgexecute.py", line 39, in _wait_select\n    state = conn.poll()\npsycopg2.OperationalError: FATAL:  password authentication failed for user "rpoole"\n\n'
2021-03-24 17:28:22,458 (15252/MainThread) pgcli.main INFO - Default pager found in PAGER environment variable: "less"
2021-03-24 17:28:22,458 (15252/MainThread) pgcli.main WARNING - import keyring failed: ModuleNotFoundError("No module named 'keyring'").
2021-03-24 17:28:24,379 (15252/MainThread) pgcli.main ERROR - traceback: 'Traceback (most recent call last):\n  File "/home/rpoole/.pyenv/versions/3.9.1/lib/python3.9/site-packages/pgcli/main.py", line 569, in connect\n    pgexecute = PGExecute(database, user, passwd, host, port, dsn, **kwargs)\n  File "/home/rpoole/.pyenv/versions/3.9.1/lib/python3.9/site-packages/pgcli/pgexecute.py", line 214, in __init__\n    self.connect(database, user, password, host, port, dsn, **kwargs)\n  File "/home/rpoole/.pyenv/versions/3.9.1/lib/python3.9/site-packages/pgcli/pgexecute.py", line 254, in connect\n    conn = psycopg2.connect(**conn_params)\n  File "/home/rpoole/.pyenv/versions/3.9.1/lib/python3.9/site-packages/psycopg2/__init__.py", line 127, in connect\n    conn = _connect(dsn, connection_factory=connection_factory, **kwasync)\n  File "/home/rpoole/.pyenv/versions/3.9.1/lib/python3.9/site-packages/pgcli/pgexecute.py", line 39, in _wait_select\n    state = conn.poll()\npsycopg2.OperationalError: fe_sendauth: no password supplied\n\n\nDuring handling of the above exception, another exception occurred:\n\nTraceback (most recent call last):\n  File "/home/rpoole/.pyenv/versions/3.9.1/lib/python3.9/site-packages/pgcli/main.py", line 578, in connect\n    pgexecute = PGExecute(\n  File "/home/rpoole/.pyenv/versions/3.9.1/lib/python3.9/site-packages/pgcli/pgexecute.py", line 214, in __init__\n    self.connect(database, user, password, host, port, dsn, **kwargs)\n  File "/home/rpoole/.pyenv/versions/3.9.1/lib/python3.9/site-packages/pgcli/pgexecute.py", line 254, in connect\n    conn = psycopg2.connect(**conn_params)\n  File "/home/rpoole/.pyenv/versions/3.9.1/lib/python3.9/site-packages/psycopg2/__init__.py", line 127, in connect\n    conn = _connect(dsn, connection_factory=connection_factory, **kwasync)\n  File "/home/rpoole/.pyenv/versions/3.9.1/lib/python3.9/site-packages/pgcli/pgexecute.py", line 39, in _wait_select\n    state = conn.poll()\npsycopg2.OperationalError: FATAL:  password authentication failed for user "postgres"\n\n'
2021-03-24 17:28:26,418 (15383/MainThread) pgcli.main INFO - Default pager found in PAGER environment variable: "less"
2021-03-24 17:28:26,419 (15383/MainThread) pgcli.main WARNING - import keyring failed: ModuleNotFoundError("No module named 'keyring'").
2021-03-24 17:32:06,297 (18662/MainThread) pgcli.main INFO - Default pager found in PAGER environment variable: "less"
2021-03-24 17:32:06,298 (18662/MainThread) pgcli.main WARNING - import keyring failed: ModuleNotFoundError("No module named 'keyring'").
2021-03-24 17:32:11,681 (18662/MainThread) pgcli.main ERROR - traceback: 'Traceback (most recent call last):\n  File "/home/rpoole/.pyenv/versions/3.9.1/lib/python3.9/site-packages/pgcli/main.py", line 569, in connect\n    pgexecute = PGExecute(database, user, passwd, host, port, dsn, **kwargs)\n  File "/home/rpoole/.pyenv/versions/3.9.1/lib/python3.9/site-packages/pgcli/pgexecute.py", line 214, in __init__\n    self.connect(database, user, password, host, port, dsn, **kwargs)\n  File "/home/rpoole/.pyenv/versions/3.9.1/lib/python3.9/site-packages/pgcli/pgexecute.py", line 254, in connect\n    conn = psycopg2.connect(**conn_params)\n  File "/home/rpoole/.pyenv/versions/3.9.1/lib/python3.9/site-packages/psycopg2/__init__.py", line 127, in connect\n    conn = _connect(dsn, connection_factory=connection_factory, **kwasync)\n  File "/home/rpoole/.pyenv/versions/3.9.1/lib/python3.9/site-packages/pgcli/pgexecute.py", line 39, in _wait_select\n    state = conn.poll()\npsycopg2.OperationalError: fe_sendauth: no password supplied\n\n\nDuring handling of the above exception, another exception occurred:\n\nTraceback (most recent call last):\n  File "/home/rpoole/.pyenv/versions/3.9.1/lib/python3.9/site-packages/click/termui.py", line 129, in prompt_func\n    return f("")\n  File "/home/rpoole/.pyenv/versions/3.9.1/lib/python3.9/site-packages/click/termui.py", line 54, in hidden_prompt_func\n    return getpass.getpass(prompt)\n  File "/home/rpoole/.pyenv/versions/3.9.1/lib/python3.9/getpass.py", line 77, in unix_getpass\n    passwd = _raw_input(prompt, stream, input=input)\n  File "/home/rpoole/.pyenv/versions/3.9.1/lib/python3.9/getpass.py", line 146, in _raw_input\n    line = input.readline()\nKeyboardInterrupt\n\nDuring handling of the above exception, another exception occurred:\n\nTraceback (most recent call last):\n  File "/home/rpoole/.pyenv/versions/3.9.1/lib/python3.9/site-packages/pgcli/main.py", line 572, in connect\n    passwd = click.prompt(\n  File "/home/rpoole/.pyenv/versions/3.9.1/lib/python3.9/site-packages/click/termui.py", line 147, in prompt\n    value = prompt_func(prompt)\n  File "/home/rpoole/.pyenv/versions/3.9.1/lib/python3.9/site-packages/click/termui.py", line 136, in prompt_func\n    raise Abort()\nclick.exceptions.Abort\n'
2021-03-24 17:32:49,840 (19234/MainThread) pgcli.main INFO - Default pager found in PAGER environment variable: "less"
2021-03-24 17:32:49,841 (19234/MainThread) pgcli.main WARNING - import keyring failed: ModuleNotFoundError("No module named 'keyring'").
2021-03-24 17:32:50,853 (19234/MainThread) pgcli.main ERROR - traceback: 'Traceback (most recent call last):\n  File "/home/rpoole/.pyenv/versions/3.9.1/lib/python3.9/site-packages/pgcli/main.py", line 569, in connect\n    pgexecute = PGExecute(database, user, passwd, host, port, dsn, **kwargs)\n  File "/home/rpoole/.pyenv/versions/3.9.1/lib/python3.9/site-packages/pgcli/pgexecute.py", line 214, in __init__\n    self.connect(database, user, password, host, port, dsn, **kwargs)\n  File "/home/rpoole/.pyenv/versions/3.9.1/lib/python3.9/site-packages/pgcli/pgexecute.py", line 254, in connect\n    conn = psycopg2.connect(**conn_params)\n  File "/home/rpoole/.pyenv/versions/3.9.1/lib/python3.9/site-packages/psycopg2/__init__.py", line 127, in connect\n    conn = _connect(dsn, connection_factory=connection_factory, **kwasync)\n  File "/home/rpoole/.pyenv/versions/3.9.1/lib/python3.9/site-packages/pgcli/pgexecute.py", line 39, in _wait_select\n    state = conn.poll()\npsycopg2.OperationalError: fe_sendauth: no password supplied\n\n\nDuring handling of the above exception, another exception occurred:\n\nTraceback (most recent call last):\n  File "/home/rpoole/.pyenv/versions/3.9.1/lib/python3.9/site-packages/click/termui.py", line 129, in prompt_func\n    return f("")\n  File "/home/rpoole/.pyenv/versions/3.9.1/lib/python3.9/site-packages/click/termui.py", line 54, in hidden_prompt_func\n    return getpass.getpass(prompt)\n  File "/home/rpoole/.pyenv/versions/3.9.1/lib/python3.9/getpass.py", line 77, in unix_getpass\n    passwd = _raw_input(prompt, stream, input=input)\n  File "/home/rpoole/.pyenv/versions/3.9.1/lib/python3.9/getpass.py", line 146, in _raw_input\n    line = input.readline()\nKeyboardInterrupt\n\nDuring handling of the above exception, another exception occurred:\n\nTraceback (most recent call last):\n  File "/home/rpoole/.pyenv/versions/3.9.1/lib/python3.9/site-packages/pgcli/main.py", line 572, in connect\n    passwd = click.prompt(\n  File "/home/rpoole/.pyenv/versions/3.9.1/lib/python3.9/site-packages/click/termui.py", line 147, in prompt\n    value = prompt_func(prompt)\n  File "/home/rpoole/.pyenv/versions/3.9.1/lib/python3.9/site-packages/click/termui.py", line 136, in prompt_func\n    raise Abort()\nclick.exceptions.Abort\n'
2021-03-24 17:32:58,711 (19365/MainThread) pgcli.main INFO - Default pager found in PAGER environment variable: "less"
2021-03-24 17:32:58,711 (19365/MainThread) pgcli.main WARNING - import keyring failed: ModuleNotFoundError("No module named 'keyring'").
2021-03-24 17:33:08,403 (19548/MainThread) pgcli.main INFO - Default pager found in PAGER environment variable: "less"
2021-03-24 17:33:08,403 (19548/MainThread) pgcli.main WARNING - import keyring failed: ModuleNotFoundError("No module named 'keyring'").
2021-04-12 20:17:15,208 (9954/MainThread) pgcli.main INFO - Default pager found in PAGER environment variable: "less"
2021-04-12 20:17:15,209 (9954/MainThread) pgcli.main WARNING - import keyring failed: ModuleNotFoundError("No module named 'keyring'").
2021-04-12 20:17:15,213 (9954/MainThread) pgcli.main ERROR - traceback: 'Traceback (most recent call last):\n  File "/home/rpoole/.pyenv/versions/3.9.1/lib/python3.9/site-packages/pgcli/main.py", line 582, in connect\n    raise e\n  File "/home/rpoole/.pyenv/versions/3.9.1/lib/python3.9/site-packages/pgcli/main.py", line 569, in connect\n    pgexecute = PGExecute(database, user, passwd, host, port, dsn, **kwargs)\n  File "/home/rpoole/.pyenv/versions/3.9.1/lib/python3.9/site-packages/pgcli/pgexecute.py", line 214, in __init__\n    self.connect(database, user, password, host, port, dsn, **kwargs)\n  File "/home/rpoole/.pyenv/versions/3.9.1/lib/python3.9/site-packages/pgcli/pgexecute.py", line 254, in connect\n    conn = psycopg2.connect(**conn_params)\n  File "/home/rpoole/.pyenv/versions/3.9.1/lib/python3.9/site-packages/psycopg2/__init__.py", line 127, in connect\n    conn = _connect(dsn, connection_factory=connection_factory, **kwasync)\npsycopg2.OperationalError: could not connect to server: No such file or directory\n\tIs the server running locally and accepting\n\tconnections on Unix domain socket "/var/run/postgresql/.s.PGSQL.5432"?\n\n'
2021-04-12 20:18:01,223 (10688/MainThread) pgcli.main INFO - Default pager found in PAGER environment variable: "less"
2021-04-12 20:18:01,223 (10688/MainThread) pgcli.main WARNING - import keyring failed: ModuleNotFoundError("No module named 'keyring'").
2021-04-13 19:08:30,666 (17402/MainThread) pgcli.main INFO - Default pager found in PAGER environment variable: "less"
2021-04-13 19:08:30,666 (17402/MainThread) pgcli.main WARNING - import keyring failed: ModuleNotFoundError("No module named 'keyring'").
2021-04-14 19:12:51,238 (22462/MainThread) pgcli.main INFO - Default pager found in PAGER environment variable: "less"
2021-04-14 19:13:44,993 (22728/MainThread) pgcli.main INFO - Default pager found in PAGER environment variable: "less"
2021-04-14 19:14:10,114 (23431/MainThread) pgcli.main INFO - Default pager found in PAGER environment variable: "less"
2021-05-16 11:21:07,927 (10425/MainThread) pgcli.main INFO - Default pager found in PAGER environment variable: "less"
2021-05-16 12:14:56,251 (10425/MainThread) pgcli.pgexecute ERROR - sql: '\\dt', error: OperationalError('server closed the connection unexpectedly\n\tThis probably means the server terminated abnormally\n\tbefore or while processing the request.\n')
2021-05-16 12:14:56,255 (10425/MainThread) pgcli.pgexecute ERROR - traceback: 'Traceback (most recent call last):\n  File "/home/rpoole/.pyenv/versions/3.9.1/lib/python3.9/site-packages/pgcli/pgexecute.py", line 398, in run\n    for result in pgspecial.execute(cur, sql):\n  File "/home/rpoole/.pyenv/versions/3.9.1/lib/python3.9/site-packages/pgspecial/main.py", line 117, in execute\n    return special_cmd.handler(cur=cur, pattern=pattern, verbose=verbose)\n  File "/home/rpoole/.pyenv/versions/3.9.1/lib/python3.9/site-packages/pgspecial/dbcommands.py", line 419, in list_tables\n    return list_objects(cur, pattern, verbose, ["r", "p", ""])\n  File "/home/rpoole/.pyenv/versions/3.9.1/lib/python3.9/site-packages/pgspecial/dbcommands.py", line 410, in list_objects\n    cur.execute(sql)\n  File "/home/rpoole/.pyenv/versions/3.9.1/lib/python3.9/site-packages/pgcli/pgexecute.py", line 39, in _wait_select\n    state = conn.poll()\npsycopg2.OperationalError: server closed the connection unexpectedly\n\tThis probably means the server terminated abnormally\n\tbefore or while processing the request.\n\n'
2021-05-16 12:14:56,255 (10425/MainThread) pgcli.main ERROR - sql: '\\dt', error: OperationalError('server closed the connection unexpectedly\n\tThis probably means the server terminated abnormally\n\tbefore or while processing the request.\n')
2021-05-16 12:14:56,256 (10425/MainThread) pgcli.main ERROR - traceback: 'Traceback (most recent call last):\n  File "/home/rpoole/.pyenv/versions/3.9.1/lib/python3.9/site-packages/pgcli/main.py", line 654, in execute_command\n    output, query = self._evaluate_command(text)\n  File "/home/rpoole/.pyenv/versions/3.9.1/lib/python3.9/site-packages/pgcli/main.py", line 901, in _evaluate_command\n    for title, cur, headers, status, sql, success, is_special in res:\n  File "/home/rpoole/.pyenv/versions/3.9.1/lib/python3.9/site-packages/pgcli/pgexecute.py", line 398, in run\n    for result in pgspecial.execute(cur, sql):\n  File "/home/rpoole/.pyenv/versions/3.9.1/lib/python3.9/site-packages/pgspecial/main.py", line 117, in execute\n    return special_cmd.handler(cur=cur, pattern=pattern, verbose=verbose)\n  File "/home/rpoole/.pyenv/versions/3.9.1/lib/python3.9/site-packages/pgspecial/dbcommands.py", line 419, in list_tables\n    return list_objects(cur, pattern, verbose, ["r", "p", ""])\n  File "/home/rpoole/.pyenv/versions/3.9.1/lib/python3.9/site-packages/pgspecial/dbcommands.py", line 410, in list_objects\n    cur.execute(sql)\n  File "/home/rpoole/.pyenv/versions/3.9.1/lib/python3.9/site-packages/pgcli/pgexecute.py", line 39, in _wait_select\n    state = conn.poll()\npsycopg2.OperationalError: server closed the connection unexpectedly\n\tThis probably means the server terminated abnormally\n\tbefore or while processing the request.\n\n'
2021-05-16 12:15:03,753 (25255/MainThread) pgcli.main INFO - Default pager found in PAGER environment variable: "less"
2021-05-16 12:37:20,318 (28938/MainThread) pgcli.main INFO - Default pager found in PAGER environment variable: "less"
2021-05-16 12:47:00,838 (28938/MainThread) pgcli.pgexecute ERROR - sql: '\\d dota_immortals_mintedplay', error: OperationalError('server closed the connection unexpectedly\n\tThis probably means the server terminated abnormally\n\tbefore or while processing the request.\n')
2021-05-16 12:47:00,839 (28938/MainThread) pgcli.pgexecute ERROR - traceback: 'Traceback (most recent call last):\n  File "/home/rpoole/.pyenv/versions/3.9.1/lib/python3.9/site-packages/pgcli/pgexecute.py", line 398, in run\n    for result in pgspecial.execute(cur, sql):\n  File "/home/rpoole/.pyenv/versions/3.9.1/lib/python3.9/site-packages/pgspecial/main.py", line 117, in execute\n    return special_cmd.handler(cur=cur, pattern=pattern, verbose=verbose)\n  File "/home/rpoole/.pyenv/versions/3.9.1/lib/python3.9/site-packages/pgspecial/dbcommands.py", line 847, in describe_table_details\n    cur.execute(sql)\n  File "/home/rpoole/.pyenv/versions/3.9.1/lib/python3.9/site-packages/pgcli/pgexecute.py", line 39, in _wait_select\n    state = conn.poll()\npsycopg2.OperationalError: server closed the connection unexpectedly\n\tThis probably means the server terminated abnormally\n\tbefore or while processing the request.\n\n'
2021-05-16 12:47:00,839 (28938/MainThread) pgcli.main ERROR - sql: '\\d dota_immortals_mintedplay', error: OperationalError('server closed the connection unexpectedly\n\tThis probably means the server terminated abnormally\n\tbefore or while processing the request.\n')
2021-05-16 12:47:00,839 (28938/MainThread) pgcli.main ERROR - traceback: 'Traceback (most recent call last):\n  File "/home/rpoole/.pyenv/versions/3.9.1/lib/python3.9/site-packages/pgcli/main.py", line 654, in execute_command\n    output, query = self._evaluate_command(text)\n  File "/home/rpoole/.pyenv/versions/3.9.1/lib/python3.9/site-packages/pgcli/main.py", line 901, in _evaluate_command\n    for title, cur, headers, status, sql, success, is_special in res:\n  File "/home/rpoole/.pyenv/versions/3.9.1/lib/python3.9/site-packages/pgcli/pgexecute.py", line 398, in run\n    for result in pgspecial.execute(cur, sql):\n  File "/home/rpoole/.pyenv/versions/3.9.1/lib/python3.9/site-packages/pgspecial/main.py", line 117, in execute\n    return special_cmd.handler(cur=cur, pattern=pattern, verbose=verbose)\n  File "/home/rpoole/.pyenv/versions/3.9.1/lib/python3.9/site-packages/pgspecial/dbcommands.py", line 847, in describe_table_details\n    cur.execute(sql)\n  File "/home/rpoole/.pyenv/versions/3.9.1/lib/python3.9/site-packages/pgcli/pgexecute.py", line 39, in _wait_select\n    state = conn.poll()\npsycopg2.OperationalError: server closed the connection unexpectedly\n\tThis probably means the server terminated abnormally\n\tbefore or while processing the request.\n\n'
2021-05-16 12:47:02,862 (31998/MainThread) pgcli.main INFO - Default pager found in PAGER environment variable: "less"
2021-05-16 13:04:28,154 (3006/MainThread) pgcli.main INFO - Default pager found in config file: "less -SRXF"
2021-05-16 13:13:32,731 (3006/MainThread) pgcli.pgexecute ERROR - sql: '\\', error: SyntaxError('syntax error at or near "\\"\nLINE 1: \\\n        ^\n')
2021-05-16 13:13:32,731 (3006/MainThread) pgcli.pgexecute ERROR - traceback: 'Traceback (most recent call last):\n  File "/home/rpoole/.pyenv/versions/3.9.1/lib/python3.9/site-packages/pgcli/pgexecute.py", line 409, in run\n    yield self.execute_normal_sql(sql) + (sql, True, False)\n  File "/home/rpoole/.pyenv/versions/3.9.1/lib/python3.9/site-packages/pgcli/pgexecute.py", line 444, in execute_normal_sql\n    cur.execute(split_sql)\npsycopg2.errors.SyntaxError: syntax error at or near "\\"\nLINE 1: \\\n        ^\n\n'
2021-05-16 13:40:08,044 (3006/MainThread) pgcli.pgexecute ERROR - sql: "'", error: SyntaxError('unterminated quoted string at or near "\'"\nLINE 1: \'\n        ^\n')
2021-05-16 13:40:08,044 (3006/MainThread) pgcli.pgexecute ERROR - traceback: 'Traceback (most recent call last):\n  File "/home/rpoole/.pyenv/versions/3.9.1/lib/python3.9/site-packages/pgcli/pgexecute.py", line 409, in run\n    yield self.execute_normal_sql(sql) + (sql, True, False)\n  File "/home/rpoole/.pyenv/versions/3.9.1/lib/python3.9/site-packages/pgcli/pgexecute.py", line 444, in execute_normal_sql\n    cur.execute(split_sql)\npsycopg2.errors.SyntaxError: unterminated quoted string at or near "\'"\nLINE 1: \'\n        ^\n\n'
2021-05-16 13:40:12,723 (10055/MainThread) pgcli.main INFO - Default pager found in config file: "less -SRXF"
2021-05-16 14:33:00,498 (21086/MainThread) pgcli.main INFO - Default pager found in config file: "less -SRXF"
2021-05-17 18:34:44,831 (21086/MainThread) pgcli.pgexecute ERROR - sql: 'update dota_immortals_purchasehistory set user_id = 2', error: OperationalError('server closed the connection unexpectedly\n\tThis probably means the server terminated abnormally\n\tbefore or while processing the request.\n')
2021-05-17 18:34:44,831 (21086/MainThread) pgcli.pgexecute ERROR - traceback: 'Traceback (most recent call last):\n  File "/home/rpoole/.pyenv/versions/3.9.1/lib/python3.9/site-packages/pgcli/pgexecute.py", line 409, in run\n    yield self.execute_normal_sql(sql) + (sql, True, False)\n  File "/home/rpoole/.pyenv/versions/3.9.1/lib/python3.9/site-packages/pgcli/pgexecute.py", line 444, in execute_normal_sql\n    cur.execute(split_sql)\n  File "/home/rpoole/.pyenv/versions/3.9.1/lib/python3.9/site-packages/pgcli/pgexecute.py", line 39, in _wait_select\n    state = conn.poll()\npsycopg2.OperationalError: server closed the connection unexpectedly\n\tThis probably means the server terminated abnormally\n\tbefore or while processing the request.\n\n'
2021-05-17 18:34:44,831 (21086/MainThread) pgcli.main ERROR - sql: 'update dota_immortals_purchasehistory set user_id = 2;', error: OperationalError('server closed the connection unexpectedly\n\tThis probably means the server terminated abnormally\n\tbefore or while processing the request.\n')
2021-05-17 18:34:44,831 (21086/MainThread) pgcli.main ERROR - traceback: 'Traceback (most recent call last):\n  File "/home/rpoole/.pyenv/versions/3.9.1/lib/python3.9/site-packages/pgcli/main.py", line 654, in execute_command\n    output, query = self._evaluate_command(text)\n  File "/home/rpoole/.pyenv/versions/3.9.1/lib/python3.9/site-packages/pgcli/main.py", line 901, in _evaluate_command\n    for title, cur, headers, status, sql, success, is_special in res:\n  File "/home/rpoole/.pyenv/versions/3.9.1/lib/python3.9/site-packages/pgcli/pgexecute.py", line 409, in run\n    yield self.execute_normal_sql(sql) + (sql, True, False)\n  File "/home/rpoole/.pyenv/versions/3.9.1/lib/python3.9/site-packages/pgcli/pgexecute.py", line 444, in execute_normal_sql\n    cur.execute(split_sql)\n  File "/home/rpoole/.pyenv/versions/3.9.1/lib/python3.9/site-packages/pgcli/pgexecute.py", line 39, in _wait_select\n    state = conn.poll()\npsycopg2.OperationalError: server closed the connection unexpectedly\n\tThis probably means the server terminated abnormally\n\tbefore or while processing the request.\n\n'
2021-05-19 23:45:33,506 (21086/MainThread) pgcli.pgexecute ERROR - sql: 'select * from dota_immortals_pack', error: OperationalError('server closed the connection unexpectedly\n\tThis probably means the server terminated abnormally\n\tbefore or while processing the request.\n')
2021-05-19 23:45:33,506 (21086/MainThread) pgcli.pgexecute ERROR - traceback: 'Traceback (most recent call last):\n  File "/home/rpoole/.pyenv/versions/3.9.1/lib/python3.9/site-packages/pgcli/pgexecute.py", line 409, in run\n    yield self.execute_normal_sql(sql) + (sql, True, False)\n  File "/home/rpoole/.pyenv/versions/3.9.1/lib/python3.9/site-packages/pgcli/pgexecute.py", line 444, in execute_normal_sql\n    cur.execute(split_sql)\n  File "/home/rpoole/.pyenv/versions/3.9.1/lib/python3.9/site-packages/pgcli/pgexecute.py", line 39, in _wait_select\n    state = conn.poll()\npsycopg2.OperationalError: server closed the connection unexpectedly\n\tThis probably means the server terminated abnormally\n\tbefore or while processing the request.\n\n'
2021-05-19 23:45:33,506 (21086/MainThread) pgcli.main ERROR - sql: 'select * from dota_immortals_pack;', error: OperationalError('server closed the connection unexpectedly\n\tThis probably means the server terminated abnormally\n\tbefore or while processing the request.\n')
2021-05-19 23:45:33,506 (21086/MainThread) pgcli.main ERROR - traceback: 'Traceback (most recent call last):\n  File "/home/rpoole/.pyenv/versions/3.9.1/lib/python3.9/site-packages/pgcli/main.py", line 654, in execute_command\n    output, query = self._evaluate_command(text)\n  File "/home/rpoole/.pyenv/versions/3.9.1/lib/python3.9/site-packages/pgcli/main.py", line 901, in _evaluate_command\n    for title, cur, headers, status, sql, success, is_special in res:\n  File "/home/rpoole/.pyenv/versions/3.9.1/lib/python3.9/site-packages/pgcli/pgexecute.py", line 409, in run\n    yield self.execute_normal_sql(sql) + (sql, True, False)\n  File "/home/rpoole/.pyenv/versions/3.9.1/lib/python3.9/site-packages/pgcli/pgexecute.py", line 444, in execute_normal_sql\n    cur.execute(split_sql)\n  File "/home/rpoole/.pyenv/versions/3.9.1/lib/python3.9/site-packages/pgcli/pgexecute.py", line 39, in _wait_select\n    state = conn.poll()\npsycopg2.OperationalError: server closed the connection unexpectedly\n\tThis probably means the server terminated abnormally\n\tbefore or while processing the request.\n\n'
2021-05-20 00:12:08,707 (21086/MainThread) pgcli.pgexecute ERROR - sql: 'select * from dota_immortals_team join dota_immortals_playteam ON dota_immortals_playteam.team_id = dota_immortals_team.id join', error: SyntaxError('syntax error at end of input\nLINE 1: ...ota_immortals_playteam.team_id = dota_immortals_team.id join\n                                                                       ^\n')
2021-05-20 00:12:08,707 (21086/MainThread) pgcli.pgexecute ERROR - traceback: 'Traceback (most recent call last):\n  File "/home/rpoole/.pyenv/versions/3.9.1/lib/python3.9/site-packages/pgcli/pgexecute.py", line 409, in run\n    yield self.execute_normal_sql(sql) + (sql, True, False)\n  File "/home/rpoole/.pyenv/versions/3.9.1/lib/python3.9/site-packages/pgcli/pgexecute.py", line 444, in execute_normal_sql\n    cur.execute(split_sql)\npsycopg2.errors.SyntaxError: syntax error at end of input\nLINE 1: ...ota_immortals_playteam.team_id = dota_immortals_team.id join\n                                                                       ^\n\n'
2021-05-20 00:12:37,085 (18996/MainThread) pgcli.main INFO - Default pager found in config file: "less -SRXF"
2021-05-20 00:13:21,508 (18996/MainThread) pgcli.pgexecute ERROR - sql: 'select name from dota_immortals_team join dota_immortals_playteam ON dota_immortals_playteam.team_id = dota_immortals_team.id join dota_immortals_mintedplay on dota_immortals_mintedplay.play_id = dota_immortals_playteam.play_id join dota_immortals_mintedpack ON dota_immortals_mintedpack.id = dota_immortals_mintedplay.minted_pack_id join dota_immortals_pack ON dota_immortals_pack.id = dota_immortals_mintedpack.pack_id', error: AmbiguousColumn('column reference "name" is ambiguous\nLINE 1: select name from dota_immortals_team join dota_immortals_pla...\n               ^\n')
2021-05-20 00:13:21,508 (18996/MainThread) pgcli.pgexecute ERROR - traceback: 'Traceback (most recent call last):\n  File "/home/rpoole/.pyenv/versions/3.9.1/lib/python3.9/site-packages/pgcli/pgexecute.py", line 409, in run\n    yield self.execute_normal_sql(sql) + (sql, True, False)\n  File "/home/rpoole/.pyenv/versions/3.9.1/lib/python3.9/site-packages/pgcli/pgexecute.py", line 444, in execute_normal_sql\n    cur.execute(split_sql)\npsycopg2.errors.AmbiguousColumn: column reference "name" is ambiguous\nLINE 1: select name from dota_immortals_team join dota_immortals_pla...\n               ^\n\n'
2021-05-21 13:32:06,378 (31895/MainThread) pgcli.main INFO - Default pager found in config file: "less -SRXF"
2021-05-21 13:33:06,424 (31895/MainThread) pgcli.pgexecute ERROR - sql: 'insert into dota_immortals_player (created, modified, name, country, image_name) values (NOW(), NOW(), "Arteezy", "canada", "arteezy.png")', error: UndefinedColumn('column "Arteezy" does not exist\nLINE 1: ... name, country, image_name) values (NOW(), NOW(), "Arteezy",...\n                                                             ^\n')
2021-05-21 13:33:06,424 (31895/MainThread) pgcli.pgexecute ERROR - traceback: 'Traceback (most recent call last):\n  File "/home/rpoole/.pyenv/versions/3.9.1/lib/python3.9/site-packages/pgcli/pgexecute.py", line 409, in run\n    yield self.execute_normal_sql(sql) + (sql, True, False)\n  File "/home/rpoole/.pyenv/versions/3.9.1/lib/python3.9/site-packages/pgcli/pgexecute.py", line 444, in execute_normal_sql\n    cur.execute(split_sql)\npsycopg2.errors.UndefinedColumn: column "Arteezy" does not exist\nLINE 1: ... name, country, image_name) values (NOW(), NOW(), "Arteezy",...\n                                                             ^\n\n'
2021-05-22 14:15:02,258 (31895/MainThread) pgcli.pgexecute ERROR - sql: '\\d auth_user', error: OperationalError('server closed the connection unexpectedly\n\tThis probably means the server terminated abnormally\n\tbefore or while processing the request.\n')
2021-05-22 14:15:02,261 (31895/MainThread) pgcli.pgexecute ERROR - traceback: 'Traceback (most recent call last):\n  File "/home/rpoole/.pyenv/versions/3.9.1/lib/python3.9/site-packages/pgcli/pgexecute.py", line 398, in run\n    for result in pgspecial.execute(cur, sql):\n  File "/home/rpoole/.pyenv/versions/3.9.1/lib/python3.9/site-packages/pgspecial/main.py", line 117, in execute\n    return special_cmd.handler(cur=cur, pattern=pattern, verbose=verbose)\n  File "/home/rpoole/.pyenv/versions/3.9.1/lib/python3.9/site-packages/pgspecial/dbcommands.py", line 847, in describe_table_details\n    cur.execute(sql)\n  File "/home/rpoole/.pyenv/versions/3.9.1/lib/python3.9/site-packages/pgcli/pgexecute.py", line 39, in _wait_select\n    state = conn.poll()\npsycopg2.OperationalError: server closed the connection unexpectedly\n\tThis probably means the server terminated abnormally\n\tbefore or while processing the request.\n\n'
2021-05-22 14:15:02,261 (31895/MainThread) pgcli.main ERROR - sql: '\\d auth_user', error: OperationalError('server closed the connection unexpectedly\n\tThis probably means the server terminated abnormally\n\tbefore or while processing the request.\n')
2021-05-22 14:15:02,264 (31895/MainThread) pgcli.main ERROR - traceback: 'Traceback (most recent call last):\n  File "/home/rpoole/.pyenv/versions/3.9.1/lib/python3.9/site-packages/pgcli/main.py", line 654, in execute_command\n    output, query = self._evaluate_command(text)\n  File "/home/rpoole/.pyenv/versions/3.9.1/lib/python3.9/site-packages/pgcli/main.py", line 901, in _evaluate_command\n    for title, cur, headers, status, sql, success, is_special in res:\n  File "/home/rpoole/.pyenv/versions/3.9.1/lib/python3.9/site-packages/pgcli/pgexecute.py", line 398, in run\n    for result in pgspecial.execute(cur, sql):\n  File "/home/rpoole/.pyenv/versions/3.9.1/lib/python3.9/site-packages/pgspecial/main.py", line 117, in execute\n    return special_cmd.handler(cur=cur, pattern=pattern, verbose=verbose)\n  File "/home/rpoole/.pyenv/versions/3.9.1/lib/python3.9/site-packages/pgspecial/dbcommands.py", line 847, in describe_table_details\n    cur.execute(sql)\n  File "/home/rpoole/.pyenv/versions/3.9.1/lib/python3.9/site-packages/pgcli/pgexecute.py", line 39, in _wait_select\n    state = conn.poll()\npsycopg2.OperationalError: server closed the connection unexpectedly\n\tThis probably means the server terminated abnormally\n\tbefore or while processing the request.\n\n'
2021-05-22 15:11:33,469 (31895/MainThread) pgcli.pgexecute ERROR - sql: 'delete from auth_user where id >= 5', error: OperationalError('server closed the connection unexpectedly\n\tThis probably means the server terminated abnormally\n\tbefore or while processing the request.\n')
2021-05-22 15:11:33,469 (31895/MainThread) pgcli.pgexecute ERROR - traceback: 'Traceback (most recent call last):\n  File "/home/rpoole/.pyenv/versions/3.9.1/lib/python3.9/site-packages/pgcli/pgexecute.py", line 409, in run\n    yield self.execute_normal_sql(sql) + (sql, True, False)\n  File "/home/rpoole/.pyenv/versions/3.9.1/lib/python3.9/site-packages/pgcli/pgexecute.py", line 444, in execute_normal_sql\n    cur.execute(split_sql)\n  File "/home/rpoole/.pyenv/versions/3.9.1/lib/python3.9/site-packages/pgcli/pgexecute.py", line 39, in _wait_select\n    state = conn.poll()\npsycopg2.OperationalError: server closed the connection unexpectedly\n\tThis probably means the server terminated abnormally\n\tbefore or while processing the request.\n\n'
2021-05-22 15:11:33,469 (31895/MainThread) pgcli.main ERROR - sql: 'delete from auth_user where id >= 5;', error: OperationalError('server closed the connection unexpectedly\n\tThis probably means the server terminated abnormally\n\tbefore or while processing the request.\n')
2021-05-22 15:11:33,469 (31895/MainThread) pgcli.main ERROR - traceback: 'Traceback (most recent call last):\n  File "/home/rpoole/.pyenv/versions/3.9.1/lib/python3.9/site-packages/pgcli/main.py", line 654, in execute_command\n    output, query = self._evaluate_command(text)\n  File "/home/rpoole/.pyenv/versions/3.9.1/lib/python3.9/site-packages/pgcli/main.py", line 901, in _evaluate_command\n    for title, cur, headers, status, sql, success, is_special in res:\n  File "/home/rpoole/.pyenv/versions/3.9.1/lib/python3.9/site-packages/pgcli/pgexecute.py", line 409, in run\n    yield self.execute_normal_sql(sql) + (sql, True, False)\n  File "/home/rpoole/.pyenv/versions/3.9.1/lib/python3.9/site-packages/pgcli/pgexecute.py", line 444, in execute_normal_sql\n    cur.execute(split_sql)\n  File "/home/rpoole/.pyenv/versions/3.9.1/lib/python3.9/site-packages/pgcli/pgexecute.py", line 39, in _wait_select\n    state = conn.poll()\npsycopg2.OperationalError: server closed the connection unexpectedly\n\tThis probably means the server terminated abnormally\n\tbefore or while processing the request.\n\n'
2021-05-22 15:36:41,603 (31895/MainThread) pgcli.pgexecute ERROR - sql: '\\dl', error: OperationalError('server closed the connection unexpectedly\n\tThis probably means the server terminated abnormally\n\tbefore or while processing the request.\n')
2021-05-22 15:36:41,603 (31895/MainThread) pgcli.pgexecute ERROR - traceback: 'Traceback (most recent call last):\n  File "/home/rpoole/.pyenv/versions/3.9.1/lib/python3.9/site-packages/pgcli/pgexecute.py", line 409, in run\n    yield self.execute_normal_sql(sql) + (sql, True, False)\n  File "/home/rpoole/.pyenv/versions/3.9.1/lib/python3.9/site-packages/pgcli/pgexecute.py", line 444, in execute_normal_sql\n    cur.execute(split_sql)\n  File "/home/rpoole/.pyenv/versions/3.9.1/lib/python3.9/site-packages/pgcli/pgexecute.py", line 39, in _wait_select\n    state = conn.poll()\npsycopg2.OperationalError: server closed the connection unexpectedly\n\tThis probably means the server terminated abnormally\n\tbefore or while processing the request.\n\n'
2021-05-22 15:36:41,603 (31895/MainThread) pgcli.main ERROR - sql: '\\dl', error: OperationalError('server closed the connection unexpectedly\n\tThis probably means the server terminated abnormally\n\tbefore or while processing the request.\n')
2021-05-22 15:36:41,603 (31895/MainThread) pgcli.main ERROR - traceback: 'Traceback (most recent call last):\n  File "/home/rpoole/.pyenv/versions/3.9.1/lib/python3.9/site-packages/pgcli/main.py", line 654, in execute_command\n    output, query = self._evaluate_command(text)\n  File "/home/rpoole/.pyenv/versions/3.9.1/lib/python3.9/site-packages/pgcli/main.py", line 901, in _evaluate_command\n    for title, cur, headers, status, sql, success, is_special in res:\n  File "/home/rpoole/.pyenv/versions/3.9.1/lib/python3.9/site-packages/pgcli/pgexecute.py", line 409, in run\n    yield self.execute_normal_sql(sql) + (sql, True, False)\n  File "/home/rpoole/.pyenv/versions/3.9.1/lib/python3.9/site-packages/pgcli/pgexecute.py", line 444, in execute_normal_sql\n    cur.execute(split_sql)\n  File "/home/rpoole/.pyenv/versions/3.9.1/lib/python3.9/site-packages/pgcli/pgexecute.py", line 39, in _wait_select\n    state = conn.poll()\npsycopg2.OperationalError: server closed the connection unexpectedly\n\tThis probably means the server terminated abnormally\n\tbefore or while processing the request.\n\n'
2021-05-22 15:36:41,612 (31895/MainThread) pgcli.pgexecute ERROR - sql: '\\dl', error: SyntaxError('syntax error at or near "\\"\nLINE 1: \\dl\n        ^\n')
2021-05-22 15:36:41,613 (31895/MainThread) pgcli.pgexecute ERROR - traceback: 'Traceback (most recent call last):\n  File "/home/rpoole/.pyenv/versions/3.9.1/lib/python3.9/site-packages/pgcli/main.py", line 654, in execute_command\n    output, query = self._evaluate_command(text)\n  File "/home/rpoole/.pyenv/versions/3.9.1/lib/python3.9/site-packages/pgcli/main.py", line 901, in _evaluate_command\n    for title, cur, headers, status, sql, success, is_special in res:\n  File "/home/rpoole/.pyenv/versions/3.9.1/lib/python3.9/site-packages/pgcli/pgexecute.py", line 409, in run\n    yield self.execute_normal_sql(sql) + (sql, True, False)\n  File "/home/rpoole/.pyenv/versions/3.9.1/lib/python3.9/site-packages/pgcli/pgexecute.py", line 444, in execute_normal_sql\n    cur.execute(split_sql)\n  File "/home/rpoole/.pyenv/versions/3.9.1/lib/python3.9/site-packages/pgcli/pgexecute.py", line 39, in _wait_select\n    state = conn.poll()\npsycopg2.OperationalError: server closed the connection unexpectedly\n\tThis probably means the server terminated abnormally\n\tbefore or while processing the request.\n\n\nDuring handling of the above exception, another exception occurred:\n\nTraceback (most recent call last):\n  File "/home/rpoole/.pyenv/versions/3.9.1/lib/python3.9/site-packages/pgcli/pgexecute.py", line 409, in run\n    yield self.execute_normal_sql(sql) + (sql, True, False)\n  File "/home/rpoole/.pyenv/versions/3.9.1/lib/python3.9/site-packages/pgcli/pgexecute.py", line 444, in execute_normal_sql\n    cur.execute(split_sql)\npsycopg2.errors.SyntaxError: syntax error at or near "\\"\nLINE 1: \\dl\n        ^\n\n'
2021-05-26 19:01:20,056 (7225/MainThread) pgcli.main INFO - Default pager found in config file: "less -SRXF"
2021-05-29 09:40:36,381 (7225/MainThread) pgcli.pgexecute ERROR - sql: 'select * from dota_immortals_mintedplay', error: OperationalError('server closed the connection unexpectedly\n\tThis probably means the server terminated abnormally\n\tbefore or while processing the request.\n')
2021-05-29 09:40:36,391 (7225/MainThread) pgcli.pgexecute ERROR - traceback: 'Traceback (most recent call last):\n  File "/home/rpoole/.pyenv/versions/3.9.1/lib/python3.9/site-packages/pgcli/pgexecute.py", line 409, in run\n    yield self.execute_normal_sql(sql) + (sql, True, False)\n  File "/home/rpoole/.pyenv/versions/3.9.1/lib/python3.9/site-packages/pgcli/pgexecute.py", line 444, in execute_normal_sql\n    cur.execute(split_sql)\n  File "/home/rpoole/.pyenv/versions/3.9.1/lib/python3.9/site-packages/pgcli/pgexecute.py", line 39, in _wait_select\n    state = conn.poll()\npsycopg2.OperationalError: server closed the connection unexpectedly\n\tThis probably means the server terminated abnormally\n\tbefore or while processing the request.\n\n'
2021-05-29 09:40:36,392 (7225/MainThread) pgcli.main ERROR - sql: 'select * from dota_immortals_mintedplay;', error: OperationalError('server closed the connection unexpectedly\n\tThis probably means the server terminated abnormally\n\tbefore or while processing the request.\n')
2021-05-29 09:40:36,394 (7225/MainThread) pgcli.main ERROR - traceback: 'Traceback (most recent call last):\n  File "/home/rpoole/.pyenv/versions/3.9.1/lib/python3.9/site-packages/pgcli/main.py", line 654, in execute_command\n    output, query = self._evaluate_command(text)\n  File "/home/rpoole/.pyenv/versions/3.9.1/lib/python3.9/site-packages/pgcli/main.py", line 901, in _evaluate_command\n    for title, cur, headers, status, sql, success, is_special in res:\n  File "/home/rpoole/.pyenv/versions/3.9.1/lib/python3.9/site-packages/pgcli/pgexecute.py", line 409, in run\n    yield self.execute_normal_sql(sql) + (sql, True, False)\n  File "/home/rpoole/.pyenv/versions/3.9.1/lib/python3.9/site-packages/pgcli/pgexecute.py", line 444, in execute_normal_sql\n    cur.execute(split_sql)\n  File "/home/rpoole/.pyenv/versions/3.9.1/lib/python3.9/site-packages/pgcli/pgexecute.py", line 39, in _wait_select\n    state = conn.poll()\npsycopg2.OperationalError: server closed the connection unexpectedly\n\tThis probably means the server terminated abnormally\n\tbefore or while processing the request.\n\n'
2021-05-29 13:16:49,773 (7225/MainThread) pgcli.pgexecute ERROR - sql: 'l', error: SyntaxError('syntax error at or near "l"\nLINE 1: l\n        ^\n')
2021-05-29 13:16:49,773 (7225/MainThread) pgcli.pgexecute ERROR - traceback: 'Traceback (most recent call last):\n  File "/home/rpoole/.pyenv/versions/3.9.1/lib/python3.9/site-packages/pgcli/pgexecute.py", line 409, in run\n    yield self.execute_normal_sql(sql) + (sql, True, False)\n  File "/home/rpoole/.pyenv/versions/3.9.1/lib/python3.9/site-packages/pgcli/pgexecute.py", line 444, in execute_normal_sql\n    cur.execute(split_sql)\npsycopg2.errors.SyntaxError: syntax error at or near "l"\nLINE 1: l\n        ^\n\n'
2021-05-30 12:02:18,750 (7225/MainThread) pgcli.pgexecute ERROR - sql: '\\dt', error: OperationalError('server closed the connection unexpectedly\n\tThis probably means the server terminated abnormally\n\tbefore or while processing the request.\n')
2021-05-30 12:02:18,754 (7225/MainThread) pgcli.pgexecute ERROR - traceback: 'Traceback (most recent call last):\n  File "/home/rpoole/.pyenv/versions/3.9.1/lib/python3.9/site-packages/pgcli/pgexecute.py", line 398, in run\n    for result in pgspecial.execute(cur, sql):\n  File "/home/rpoole/.pyenv/versions/3.9.1/lib/python3.9/site-packages/pgspecial/main.py", line 117, in execute\n    return special_cmd.handler(cur=cur, pattern=pattern, verbose=verbose)\n  File "/home/rpoole/.pyenv/versions/3.9.1/lib/python3.9/site-packages/pgspecial/dbcommands.py", line 419, in list_tables\n    return list_objects(cur, pattern, verbose, ["r", "p", ""])\n  File "/home/rpoole/.pyenv/versions/3.9.1/lib/python3.9/site-packages/pgspecial/dbcommands.py", line 410, in list_objects\n    cur.execute(sql)\n  File "/home/rpoole/.pyenv/versions/3.9.1/lib/python3.9/site-packages/pgcli/pgexecute.py", line 39, in _wait_select\n    state = conn.poll()\npsycopg2.OperationalError: server closed the connection unexpectedly\n\tThis probably means the server terminated abnormally\n\tbefore or while processing the request.\n\n'
2021-05-30 12:02:18,754 (7225/MainThread) pgcli.main ERROR - sql: '\\dt', error: OperationalError('server closed the connection unexpectedly\n\tThis probably means the server terminated abnormally\n\tbefore or while processing the request.\n')
2021-05-30 12:02:18,754 (7225/MainThread) pgcli.main ERROR - traceback: 'Traceback (most recent call last):\n  File "/home/rpoole/.pyenv/versions/3.9.1/lib/python3.9/site-packages/pgcli/main.py", line 654, in execute_command\n    output, query = self._evaluate_command(text)\n  File "/home/rpoole/.pyenv/versions/3.9.1/lib/python3.9/site-packages/pgcli/main.py", line 901, in _evaluate_command\n    for title, cur, headers, status, sql, success, is_special in res:\n  File "/home/rpoole/.pyenv/versions/3.9.1/lib/python3.9/site-packages/pgcli/pgexecute.py", line 398, in run\n    for result in pgspecial.execute(cur, sql):\n  File "/home/rpoole/.pyenv/versions/3.9.1/lib/python3.9/site-packages/pgspecial/main.py", line 117, in execute\n    return special_cmd.handler(cur=cur, pattern=pattern, verbose=verbose)\n  File "/home/rpoole/.pyenv/versions/3.9.1/lib/python3.9/site-packages/pgspecial/dbcommands.py", line 419, in list_tables\n    return list_objects(cur, pattern, verbose, ["r", "p", ""])\n  File "/home/rpoole/.pyenv/versions/3.9.1/lib/python3.9/site-packages/pgspecial/dbcommands.py", line 410, in list_objects\n    cur.execute(sql)\n  File "/home/rpoole/.pyenv/versions/3.9.1/lib/python3.9/site-packages/pgcli/pgexecute.py", line 39, in _wait_select\n    state = conn.poll()\npsycopg2.OperationalError: server closed the connection unexpectedly\n\tThis probably means the server terminated abnormally\n\tbefore or while processing the request.\n\n'
2021-05-30 15:53:08,795 (7225/MainThread) pgcli.pgexecute ERROR - sql: 'delete from django_session', error: OperationalError('server closed the connection unexpectedly\n\tThis probably means the server terminated abnormally\n\tbefore or while processing the request.\n')
2021-05-30 15:53:08,796 (7225/MainThread) pgcli.pgexecute ERROR - traceback: 'Traceback (most recent call last):\n  File "/home/rpoole/.pyenv/versions/3.9.1/lib/python3.9/site-packages/pgcli/pgexecute.py", line 409, in run\n    yield self.execute_normal_sql(sql) + (sql, True, False)\n  File "/home/rpoole/.pyenv/versions/3.9.1/lib/python3.9/site-packages/pgcli/pgexecute.py", line 444, in execute_normal_sql\n    cur.execute(split_sql)\n  File "/home/rpoole/.pyenv/versions/3.9.1/lib/python3.9/site-packages/pgcli/pgexecute.py", line 39, in _wait_select\n    state = conn.poll()\npsycopg2.OperationalError: server closed the connection unexpectedly\n\tThis probably means the server terminated abnormally\n\tbefore or while processing the request.\n\n'
2021-05-30 15:53:08,796 (7225/MainThread) pgcli.main ERROR - sql: 'delete from django_session;', error: OperationalError('server closed the connection unexpectedly\n\tThis probably means the server terminated abnormally\n\tbefore or while processing the request.\n')
2021-05-30 15:53:08,796 (7225/MainThread) pgcli.main ERROR - traceback: 'Traceback (most recent call last):\n  File "/home/rpoole/.pyenv/versions/3.9.1/lib/python3.9/site-packages/pgcli/main.py", line 654, in execute_command\n    output, query = self._evaluate_command(text)\n  File "/home/rpoole/.pyenv/versions/3.9.1/lib/python3.9/site-packages/pgcli/main.py", line 901, in _evaluate_command\n    for title, cur, headers, status, sql, success, is_special in res:\n  File "/home/rpoole/.pyenv/versions/3.9.1/lib/python3.9/site-packages/pgcli/pgexecute.py", line 409, in run\n    yield self.execute_normal_sql(sql) + (sql, True, False)\n  File "/home/rpoole/.pyenv/versions/3.9.1/lib/python3.9/site-packages/pgcli/pgexecute.py", line 444, in execute_normal_sql\n    cur.execute(split_sql)\n  File "/home/rpoole/.pyenv/versions/3.9.1/lib/python3.9/site-packages/pgcli/pgexecute.py", line 39, in _wait_select\n    state = conn.poll()\npsycopg2.OperationalError: server closed the connection unexpectedly\n\tThis probably means the server terminated abnormally\n\tbefore or while processing the request.\n\n'
2021-05-30 16:47:03,001 (25194/MainThread) pgcli.main INFO - Default pager found in config file: "less -SRXF"
2021-06-03 22:51:27,227 (5602/MainThread) pgcli.main INFO - Default pager found in config file: "less -SRXF"
2021-06-03 22:51:27,272 (5602/MainThread) pgcli.main ERROR - traceback: 'Traceback (most recent call last):\n  File "/home/rpoole/.pyenv/versions/3.9.1/lib/python3.9/site-packages/pgcli/main.py", line 582, in connect\n    raise e\n  File "/home/rpoole/.pyenv/versions/3.9.1/lib/python3.9/site-packages/pgcli/main.py", line 569, in connect\n    pgexecute = PGExecute(database, user, passwd, host, port, dsn, **kwargs)\n  File "/home/rpoole/.pyenv/versions/3.9.1/lib/python3.9/site-packages/pgcli/pgexecute.py", line 214, in __init__\n    self.connect(database, user, password, host, port, dsn, **kwargs)\n  File "/home/rpoole/.pyenv/versions/3.9.1/lib/python3.9/site-packages/pgcli/pgexecute.py", line 254, in connect\n    conn = psycopg2.connect(**conn_params)\n  File "/home/rpoole/.pyenv/versions/3.9.1/lib/python3.9/site-packages/psycopg2/__init__.py", line 127, in connect\n    conn = _connect(dsn, connection_factory=connection_factory, **kwasync)\n  File "/home/rpoole/.pyenv/versions/3.9.1/lib/python3.9/site-packages/pgcli/pgexecute.py", line 39, in _wait_select\n    state = conn.poll()\npsycopg2.OperationalError: could not connect to server: Connection refused\n\tIs the server running on host "127.0.0.1" and accepting\n\tTCP/IP connections on port 5432?\n\n'
2021-06-03 22:53:28,737 (7355/MainThread) pgcli.main INFO - Default pager found in config file: "less -SRXF"
2021-06-03 22:54:52,271 (7355/MainThread) pgcli.pgexecute ERROR - sql: "delete from dota_immortals_caster where created >= '06-03-21'", error: ForeignKeyViolation('update or delete on table "dota_immortals_caster" violates foreign key constraint "dota_immortals_playc_caster_id_30db05c2_fk_dota_immo" on table "dota_immortals_playcaster"\nDETAIL:  Key (id)=(3) is still referenced from table "dota_immortals_playcaster".\n')
2021-06-03 22:54:52,272 (7355/MainThread) pgcli.pgexecute ERROR - traceback: 'Traceback (most recent call last):\n  File "/home/rpoole/.pyenv/versions/3.9.1/lib/python3.9/site-packages/pgcli/pgexecute.py", line 409, in run\n    yield self.execute_normal_sql(sql) + (sql, True, False)\n  File "/home/rpoole/.pyenv/versions/3.9.1/lib/python3.9/site-packages/pgcli/pgexecute.py", line 444, in execute_normal_sql\n    cur.execute(split_sql)\npsycopg2.errors.ForeignKeyViolation: update or delete on table "dota_immortals_caster" violates foreign key constraint "dota_immortals_playc_caster_id_30db05c2_fk_dota_immo" on table "dota_immortals_playcaster"\nDETAIL:  Key (id)=(3) is still referenced from table "dota_immortals_playcaster".\n\n'
2021-06-03 22:55:32,424 (7355/MainThread) pgcli.pgexecute ERROR - sql: "delete from dota_immortals_hero where created >= '06-03-21'", error: ForeignKeyViolation('update or delete on table "dota_immortals_hero" violates foreign key constraint "dota_immortals_play_hero_id_1057380d_fk_dota_immortals_hero_id" on table "dota_immortals_play"\nDETAIL:  Key (id)=(2) is still referenced from table "dota_immortals_play".\n')
2021-06-03 22:55:32,425 (7355/MainThread) pgcli.pgexecute ERROR - traceback: 'Traceback (most recent call last):\n  File "/home/rpoole/.pyenv/versions/3.9.1/lib/python3.9/site-packages/pgcli/pgexecute.py", line 409, in run\n    yield self.execute_normal_sql(sql) + (sql, True, False)\n  File "/home/rpoole/.pyenv/versions/3.9.1/lib/python3.9/site-packages/pgcli/pgexecute.py", line 444, in execute_normal_sql\n    cur.execute(split_sql)\npsycopg2.errors.ForeignKeyViolation: update or delete on table "dota_immortals_hero" violates foreign key constraint "dota_immortals_play_hero_id_1057380d_fk_dota_immortals_hero_id" on table "dota_immortals_play"\nDETAIL:  Key (id)=(2) is still referenced from table "dota_immortals_play".\n\n'
2021-06-03 22:55:38,176 (7355/MainThread) pgcli.pgexecute ERROR - sql: "delete from dota_immortals_play where created >= '06-03-21'", error: ForeignKeyViolation('update or delete on table "dota_immortals_play" violates foreign key constraint "dota_immortals_plays_play_id_1d9c0d31_fk_dota_immo" on table "dota_immortals_playsecondaryhero"\nDETAIL:  Key (id)=(3) is still referenced from table "dota_immortals_playsecondaryhero".\n')
2021-06-03 22:55:38,176 (7355/MainThread) pgcli.pgexecute ERROR - traceback: 'Traceback (most recent call last):\n  File "/home/rpoole/.pyenv/versions/3.9.1/lib/python3.9/site-packages/pgcli/pgexecute.py", line 409, in run\n    yield self.execute_normal_sql(sql) + (sql, True, False)\n  File "/home/rpoole/.pyenv/versions/3.9.1/lib/python3.9/site-packages/pgcli/pgexecute.py", line 444, in execute_normal_sql\n    cur.execute(split_sql)\npsycopg2.errors.ForeignKeyViolation: update or delete on table "dota_immortals_play" violates foreign key constraint "dota_immortals_plays_play_id_1d9c0d31_fk_dota_immo" on table "dota_immortals_playsecondaryhero"\nDETAIL:  Key (id)=(3) is still referenced from table "dota_immortals_playsecondaryhero".\n\n'
2021-06-03 22:55:45,442 (7355/MainThread) pgcli.pgexecute ERROR - sql: "delete from dota_immortals_play where created >= '06-03-21'", error: ForeignKeyViolation('update or delete on table "dota_immortals_play" violates foreign key constraint "dota_immortals_minte_play_id_6faf8fbf_fk_dota_immo" on table "dota_immortals_mintedplay"\nDETAIL:  Key (id)=(3) is still referenced from table "dota_immortals_mintedplay".\n')
2021-06-03 22:55:45,443 (7355/MainThread) pgcli.pgexecute ERROR - traceback: 'Traceback (most recent call last):\n  File "/home/rpoole/.pyenv/versions/3.9.1/lib/python3.9/site-packages/pgcli/pgexecute.py", line 409, in run\n    yield self.execute_normal_sql(sql) + (sql, True, False)\n  File "/home/rpoole/.pyenv/versions/3.9.1/lib/python3.9/site-packages/pgcli/pgexecute.py", line 444, in execute_normal_sql\n    cur.execute(split_sql)\npsycopg2.errors.ForeignKeyViolation: update or delete on table "dota_immortals_play" violates foreign key constraint "dota_immortals_minte_play_id_6faf8fbf_fk_dota_immo" on table "dota_immortals_mintedplay"\nDETAIL:  Key (id)=(3) is still referenced from table "dota_immortals_mintedplay".\n\n'
2021-06-03 22:55:55,868 (7355/MainThread) pgcli.pgexecute ERROR - sql: "delete from dota_immortals_mintedplayplay where created >= '06-03-21'", error: UndefinedTable('relation "dota_immortals_mintedplayplay" does not exist\nLINE 1: delete from dota_immortals_mintedplayplay where created >= \'...\n                    ^\n')
2021-06-03 22:55:55,868 (7355/MainThread) pgcli.pgexecute ERROR - traceback: 'Traceback (most recent call last):\n  File "/home/rpoole/.pyenv/versions/3.9.1/lib/python3.9/site-packages/pgcli/pgexecute.py", line 409, in run\n    yield self.execute_normal_sql(sql) + (sql, True, False)\n  File "/home/rpoole/.pyenv/versions/3.9.1/lib/python3.9/site-packages/pgcli/pgexecute.py", line 444, in execute_normal_sql\n    cur.execute(split_sql)\npsycopg2.errors.UndefinedTable: relation "dota_immortals_mintedplayplay" does not exist\nLINE 1: delete from dota_immortals_mintedplayplay where created >= \'...\n                    ^\n\n'
2021-06-03 22:56:04,046 (7355/MainThread) pgcli.pgexecute ERROR - sql: "delete from dota_immortals_play where created >= '06-03-21'", error: ForeignKeyViolation('update or delete on table "dota_immortals_play" violates foreign key constraint "dota_immortals_playt_play_id_dfdfbb36_fk_dota_immo" on table "dota_immortals_playteam"\nDETAIL:  Key (id)=(5) is still referenced from table "dota_immortals_playteam".\n')
2021-06-03 22:56:04,046 (7355/MainThread) pgcli.pgexecute ERROR - traceback: 'Traceback (most recent call last):\n  File "/home/rpoole/.pyenv/versions/3.9.1/lib/python3.9/site-packages/pgcli/pgexecute.py", line 409, in run\n    yield self.execute_normal_sql(sql) + (sql, True, False)\n  File "/home/rpoole/.pyenv/versions/3.9.1/lib/python3.9/site-packages/pgcli/pgexecute.py", line 444, in execute_normal_sql\n    cur.execute(split_sql)\npsycopg2.errors.ForeignKeyViolation: update or delete on table "dota_immortals_play" violates foreign key constraint "dota_immortals_playt_play_id_dfdfbb36_fk_dota_immo" on table "dota_immortals_playteam"\nDETAIL:  Key (id)=(5) is still referenced from table "dota_immortals_playteam".\n\n'
2021-06-03 22:57:59,540 (7355/MainThread) pgcli.pgexecute ERROR - sql: "delete from dota_immortal_playteam where created >= '06-03-21'", error: UndefinedTable('relation "dota_immortal_playteam" does not exist\nLINE 1: delete from dota_immortal_playteam where created >= \'06-03-2...\n                    ^\n')
2021-06-03 22:57:59,541 (7355/MainThread) pgcli.pgexecute ERROR - traceback: 'Traceback (most recent call last):\n  File "/home/rpoole/.pyenv/versions/3.9.1/lib/python3.9/site-packages/pgcli/pgexecute.py", line 409, in run\n    yield self.execute_normal_sql(sql) + (sql, True, False)\n  File "/home/rpoole/.pyenv/versions/3.9.1/lib/python3.9/site-packages/pgcli/pgexecute.py", line 444, in execute_normal_sql\n    cur.execute(split_sql)\npsycopg2.errors.UndefinedTable: relation "dota_immortal_playteam" does not exist\nLINE 1: delete from dota_immortal_playteam where created >= \'06-03-2...\n                    ^\n\n'
2021-06-03 22:58:13,886 (7355/MainThread) pgcli.pgexecute ERROR - sql: "delete from dota_immortals_purchasehistory_ where created >= '06-03-21'", error: UndefinedTable('relation "dota_immortals_purchasehistory_" does not exist\nLINE 1: delete from dota_immortals_purchasehistory_ where created >=...\n                    ^\n')
2021-06-03 22:58:13,887 (7355/MainThread) pgcli.pgexecute ERROR - traceback: 'Traceback (most recent call last):\n  File "/home/rpoole/.pyenv/versions/3.9.1/lib/python3.9/site-packages/pgcli/pgexecute.py", line 409, in run\n    yield self.execute_normal_sql(sql) + (sql, True, False)\n  File "/home/rpoole/.pyenv/versions/3.9.1/lib/python3.9/site-packages/pgcli/pgexecute.py", line 444, in execute_normal_sql\n    cur.execute(split_sql)\npsycopg2.errors.UndefinedTable: relation "dota_immortals_purchasehistory_" does not exist\nLINE 1: delete from dota_immortals_purchasehistory_ where created >=...\n                    ^\n\n'
2021-06-03 23:35:08,022 (17436/MainThread) pgcli.main INFO - Default pager found in config file: "less -SRXF"
2021-06-03 23:35:27,755 (17436/MainThread) pgcli.pgexecute ERROR - sql: "delete from dota_immortals_caster where created >= '06-03-21'", error: ForeignKeyViolation('update or delete on table "dota_immortals_caster" violates foreign key constraint "dota_immortals_playc_caster_id_30db05c2_fk_dota_immo" on table "dota_immortals_playcaster"\nDETAIL:  Key (id)=(13) is still referenced from table "dota_immortals_playcaster".\n')
2021-06-03 23:35:27,757 (17436/MainThread) pgcli.pgexecute ERROR - traceback: 'Traceback (most recent call last):\n  File "/home/rpoole/.pyenv/versions/3.9.1/lib/python3.9/site-packages/pgcli/pgexecute.py", line 409, in run\n    yield self.execute_normal_sql(sql) + (sql, True, False)\n  File "/home/rpoole/.pyenv/versions/3.9.1/lib/python3.9/site-packages/pgcli/pgexecute.py", line 444, in execute_normal_sql\n    cur.execute(split_sql)\npsycopg2.errors.ForeignKeyViolation: update or delete on table "dota_immortals_caster" violates foreign key constraint "dota_immortals_playc_caster_id_30db05c2_fk_dota_immo" on table "dota_immortals_playcaster"\nDETAIL:  Key (id)=(13) is still referenced from table "dota_immortals_playcaster".\n\n'
2021-06-03 23:35:43,442 (17436/MainThread) pgcli.pgexecute ERROR - sql: "delete from dota_immortals_hero where created >= '06-03-21'", error: ForeignKeyViolation('update or delete on table "dota_immortals_hero" violates foreign key constraint "dota_immortals_play_hero_id_1057380d_fk_dota_immortals_hero_id" on table "dota_immortals_play"\nDETAIL:  Key (id)=(12) is still referenced from table "dota_immortals_play".\n')
2021-06-03 23:35:43,442 (17436/MainThread) pgcli.pgexecute ERROR - traceback: 'Traceback (most recent call last):\n  File "/home/rpoole/.pyenv/versions/3.9.1/lib/python3.9/site-packages/pgcli/pgexecute.py", line 409, in run\n    yield self.execute_normal_sql(sql) + (sql, True, False)\n  File "/home/rpoole/.pyenv/versions/3.9.1/lib/python3.9/site-packages/pgcli/pgexecute.py", line 444, in execute_normal_sql\n    cur.execute(split_sql)\npsycopg2.errors.ForeignKeyViolation: update or delete on table "dota_immortals_hero" violates foreign key constraint "dota_immortals_play_hero_id_1057380d_fk_dota_immortals_hero_id" on table "dota_immortals_play"\nDETAIL:  Key (id)=(12) is still referenced from table "dota_immortals_play".\n\n'
2021-06-03 23:35:51,623 (17436/MainThread) pgcli.pgexecute ERROR - sql: "delete from dota_immortals_play where created >= '06-03-21'", error: ForeignKeyViolation('update or delete on table "dota_immortals_play" violates foreign key constraint "dota_immortals_plays_play_id_1d9c0d31_fk_dota_immo" on table "dota_immortals_playsecondaryhero"\nDETAIL:  Key (id)=(13) is still referenced from table "dota_immortals_playsecondaryhero".\n')
2021-06-03 23:35:51,624 (17436/MainThread) pgcli.pgexecute ERROR - traceback: 'Traceback (most recent call last):\n  File "/home/rpoole/.pyenv/versions/3.9.1/lib/python3.9/site-packages/pgcli/pgexecute.py", line 409, in run\n    yield self.execute_normal_sql(sql) + (sql, True, False)\n  File "/home/rpoole/.pyenv/versions/3.9.1/lib/python3.9/site-packages/pgcli/pgexecute.py", line 444, in execute_normal_sql\n    cur.execute(split_sql)\npsycopg2.errors.ForeignKeyViolation: update or delete on table "dota_immortals_play" violates foreign key constraint "dota_immortals_plays_play_id_1d9c0d31_fk_dota_immo" on table "dota_immortals_playsecondaryhero"\nDETAIL:  Key (id)=(13) is still referenced from table "dota_immortals_playsecondaryhero".\n\n'
2021-06-03 23:35:57,250 (17436/MainThread) pgcli.pgexecute ERROR - sql: "delete from dota_immortals_play where created >= '06-03-21'", error: ForeignKeyViolation('update or delete on table "dota_immortals_play" violates foreign key constraint "dota_immortals_minte_play_id_6faf8fbf_fk_dota_immo" on table "dota_immortals_mintedplay"\nDETAIL:  Key (id)=(13) is still referenced from table "dota_immortals_mintedplay".\n')
2021-06-03 23:35:57,250 (17436/MainThread) pgcli.pgexecute ERROR - traceback: 'Traceback (most recent call last):\n  File "/home/rpoole/.pyenv/versions/3.9.1/lib/python3.9/site-packages/pgcli/pgexecute.py", line 409, in run\n    yield self.execute_normal_sql(sql) + (sql, True, False)\n  File "/home/rpoole/.pyenv/versions/3.9.1/lib/python3.9/site-packages/pgcli/pgexecute.py", line 444, in execute_normal_sql\n    cur.execute(split_sql)\npsycopg2.errors.ForeignKeyViolation: update or delete on table "dota_immortals_play" violates foreign key constraint "dota_immortals_minte_play_id_6faf8fbf_fk_dota_immo" on table "dota_immortals_mintedplay"\nDETAIL:  Key (id)=(13) is still referenced from table "dota_immortals_mintedplay".\n\n'
2021-06-03 23:36:02,481 (17436/MainThread) pgcli.pgexecute ERROR - sql: "delete from dota_immortals_play where created >= '06-03-21'", error: ForeignKeyViolation('update or delete on table "dota_immortals_play" violates foreign key constraint "dota_immortals_minte_play_id_6faf8fbf_fk_dota_immo" on table "dota_immortals_mintedplay"\nDETAIL:  Key (id)=(13) is still referenced from table "dota_immortals_mintedplay".\n')
2021-06-03 23:36:02,481 (17436/MainThread) pgcli.pgexecute ERROR - traceback: 'Traceback (most recent call last):\n  File "/home/rpoole/.pyenv/versions/3.9.1/lib/python3.9/site-packages/pgcli/pgexecute.py", line 409, in run\n    yield self.execute_normal_sql(sql) + (sql, True, False)\n  File "/home/rpoole/.pyenv/versions/3.9.1/lib/python3.9/site-packages/pgcli/pgexecute.py", line 444, in execute_normal_sql\n    cur.execute(split_sql)\npsycopg2.errors.ForeignKeyViolation: update or delete on table "dota_immortals_play" violates foreign key constraint "dota_immortals_minte_play_id_6faf8fbf_fk_dota_immo" on table "dota_immortals_mintedplay"\nDETAIL:  Key (id)=(13) is still referenced from table "dota_immortals_mintedplay".\n\n'
2021-06-03 23:45:59,354 (17436/MainThread) pgcli.pgexecute ERROR - sql: 'select * from auth_permission', error: OperationalError('server closed the connection unexpectedly\n\tThis probably means the server terminated abnormally\n\tbefore or while processing the request.\n')
2021-06-03 23:45:59,354 (17436/MainThread) pgcli.pgexecute ERROR - traceback: 'Traceback (most recent call last):\n  File "/home/rpoole/.pyenv/versions/3.9.1/lib/python3.9/site-packages/pgcli/pgexecute.py", line 409, in run\n    yield self.execute_normal_sql(sql) + (sql, True, False)\n  File "/home/rpoole/.pyenv/versions/3.9.1/lib/python3.9/site-packages/pgcli/pgexecute.py", line 444, in execute_normal_sql\n    cur.execute(split_sql)\n  File "/home/rpoole/.pyenv/versions/3.9.1/lib/python3.9/site-packages/pgcli/pgexecute.py", line 39, in _wait_select\n    state = conn.poll()\npsycopg2.OperationalError: server closed the connection unexpectedly\n\tThis probably means the server terminated abnormally\n\tbefore or while processing the request.\n\n'
2021-06-03 23:45:59,354 (17436/MainThread) pgcli.main ERROR - sql: 'select * from auth_permission;', error: OperationalError('server closed the connection unexpectedly\n\tThis probably means the server terminated abnormally\n\tbefore or while processing the request.\n')
2021-06-03 23:45:59,356 (17436/MainThread) pgcli.main ERROR - traceback: 'Traceback (most recent call last):\n  File "/home/rpoole/.pyenv/versions/3.9.1/lib/python3.9/site-packages/pgcli/main.py", line 654, in execute_command\n    output, query = self._evaluate_command(text)\n  File "/home/rpoole/.pyenv/versions/3.9.1/lib/python3.9/site-packages/pgcli/main.py", line 901, in _evaluate_command\n    for title, cur, headers, status, sql, success, is_special in res:\n  File "/home/rpoole/.pyenv/versions/3.9.1/lib/python3.9/site-packages/pgcli/pgexecute.py", line 409, in run\n    yield self.execute_normal_sql(sql) + (sql, True, False)\n  File "/home/rpoole/.pyenv/versions/3.9.1/lib/python3.9/site-packages/pgcli/pgexecute.py", line 444, in execute_normal_sql\n    cur.execute(split_sql)\n  File "/home/rpoole/.pyenv/versions/3.9.1/lib/python3.9/site-packages/pgcli/pgexecute.py", line 39, in _wait_select\n    state = conn.poll()\npsycopg2.OperationalError: server closed the connection unexpectedly\n\tThis probably means the server terminated abnormally\n\tbefore or while processing the request.\n\n'
2021-06-03 23:45:59,365 (17436/MainThread) pgcli.pgexecute ERROR - sql: 'select * from auth_permission', error: UndefinedTable('relation "auth_permission" does not exist\nLINE 1: select * from auth_permission\n                      ^\n')
2021-06-03 23:45:59,366 (17436/MainThread) pgcli.pgexecute ERROR - traceback: 'Traceback (most recent call last):\n  File "/home/rpoole/.pyenv/versions/3.9.1/lib/python3.9/site-packages/pgcli/main.py", line 654, in execute_command\n    output, query = self._evaluate_command(text)\n  File "/home/rpoole/.pyenv/versions/3.9.1/lib/python3.9/site-packages/pgcli/main.py", line 901, in _evaluate_command\n    for title, cur, headers, status, sql, success, is_special in res:\n  File "/home/rpoole/.pyenv/versions/3.9.1/lib/python3.9/site-packages/pgcli/pgexecute.py", line 409, in run\n    yield self.execute_normal_sql(sql) + (sql, True, False)\n  File "/home/rpoole/.pyenv/versions/3.9.1/lib/python3.9/site-packages/pgcli/pgexecute.py", line 444, in execute_normal_sql\n    cur.execute(split_sql)\n  File "/home/rpoole/.pyenv/versions/3.9.1/lib/python3.9/site-packages/pgcli/pgexecute.py", line 39, in _wait_select\n    state = conn.poll()\npsycopg2.OperationalError: server closed the connection unexpectedly\n\tThis probably means the server terminated abnormally\n\tbefore or while processing the request.\n\n\nDuring handling of the above exception, another exception occurred:\n\nTraceback (most recent call last):\n  File "/home/rpoole/.pyenv/versions/3.9.1/lib/python3.9/site-packages/pgcli/pgexecute.py", line 409, in run\n    yield self.execute_normal_sql(sql) + (sql, True, False)\n  File "/home/rpoole/.pyenv/versions/3.9.1/lib/python3.9/site-packages/pgcli/pgexecute.py", line 444, in execute_normal_sql\n    cur.execute(split_sql)\npsycopg2.errors.UndefinedTable: relation "auth_permission" does not exist\nLINE 1: select * from auth_permission\n                      ^\n\n'
2021-06-12 12:59:56,980 (3168/MainThread) pgcli.main INFO - Default pager found in config file: "less -SRXF"
2021-06-12 15:57:33,345 (27864/MainThread) pgcli.main INFO - Default pager found in config file: "less -SRXF"
2021-06-13 12:52:59,979 (12006/MainThread) pgcli.main INFO - Default pager found in config file: "less -SRXF"
2021-06-13 13:52:28,209 (26751/MainThread) pgcli.main INFO - Default pager found in config file: "less -SRXF"
2021-06-14 20:10:30,206 (23366/MainThread) pgcli.main INFO - Default pager found in config file: "less -SRXF"
2021-06-14 20:59:51,093 (23366/MainThread) pgcli.pgexecute ERROR - sql: 'update dota_immortals_mintedpack set drop_id = 1', error: ForeignKeyViolation('insert or update on table "dota_immortals_mintedpack" violates foreign key constraint "dota_immortals_minte_drop_id_ec9d3dcb_fk_dota_immo"\nDETAIL:  Key (drop_id)=(1) is not present in table "dota_immortals_drop".\n')
2021-06-14 20:59:51,095 (23366/MainThread) pgcli.pgexecute ERROR - traceback: 'Traceback (most recent call last):\n  File "/home/rpoole/.pyenv/versions/3.9.1/lib/python3.9/site-packages/pgcli/pgexecute.py", line 409, in run\n    yield self.execute_normal_sql(sql) + (sql, True, False)\n  File "/home/rpoole/.pyenv/versions/3.9.1/lib/python3.9/site-packages/pgcli/pgexecute.py", line 444, in execute_normal_sql\n    cur.execute(split_sql)\npsycopg2.errors.ForeignKeyViolation: insert or update on table "dota_immortals_mintedpack" violates foreign key constraint "dota_immortals_minte_drop_id_ec9d3dcb_fk_dota_immo"\nDETAIL:  Key (drop_id)=(1) is not present in table "dota_immortals_drop".\n\n'
2021-06-14 21:00:07,266 (23366/MainThread) pgcli.pgexecute ERROR - sql: 'delete from dota_immortals_mintedpack', error: ForeignKeyViolation('update or delete on table "dota_immortals_mintedpack" violates foreign key constraint "dota_immortals_minte_minted_pack_id_78cec5d3_fk_dota_immo" on table "dota_immortals_mintedplay"\nDETAIL:  Key (id)=(1) is still referenced from table "dota_immortals_mintedplay".\n')
2021-06-14 21:00:07,266 (23366/MainThread) pgcli.pgexecute ERROR - traceback: 'Traceback (most recent call last):\n  File "/home/rpoole/.pyenv/versions/3.9.1/lib/python3.9/site-packages/pgcli/pgexecute.py", line 409, in run\n    yield self.execute_normal_sql(sql) + (sql, True, False)\n  File "/home/rpoole/.pyenv/versions/3.9.1/lib/python3.9/site-packages/pgcli/pgexecute.py", line 444, in execute_normal_sql\n    cur.execute(split_sql)\npsycopg2.errors.ForeignKeyViolation: update or delete on table "dota_immortals_mintedpack" violates foreign key constraint "dota_immortals_minte_minted_pack_id_78cec5d3_fk_dota_immo" on table "dota_immortals_mintedplay"\nDETAIL:  Key (id)=(1) is still referenced from table "dota_immortals_mintedplay".\n\n'
2021-06-14 21:05:37,686 (23366/MainThread) pgcli.pgexecute ERROR - sql: "'", error: SyntaxError('unterminated quoted string at or near "\'"\nLINE 1: \'\n        ^\n')
2021-06-14 21:05:37,687 (23366/MainThread) pgcli.pgexecute ERROR - traceback: 'Traceback (most recent call last):\n  File "/home/rpoole/.pyenv/versions/3.9.1/lib/python3.9/site-packages/pgcli/pgexecute.py", line 409, in run\n    yield self.execute_normal_sql(sql) + (sql, True, False)\n  File "/home/rpoole/.pyenv/versions/3.9.1/lib/python3.9/site-packages/pgcli/pgexecute.py", line 444, in execute_normal_sql\n    cur.execute(split_sql)\npsycopg2.errors.SyntaxError: unterminated quoted string at or near "\'"\nLINE 1: \'\n        ^\n\n'
2021-06-15 17:29:03,986 (23366/MainThread) pgcli.pgexecute ERROR - sql: 'delete from dota_immortals_mintedplay', error: OperationalError('server closed the connection unexpectedly\n\tThis probably means the server terminated abnormally\n\tbefore or while processing the request.\n')
2021-06-15 17:29:03,987 (23366/MainThread) pgcli.pgexecute ERROR - traceback: 'Traceback (most recent call last):\n  File "/home/rpoole/.pyenv/versions/3.9.1/lib/python3.9/site-packages/pgcli/pgexecute.py", line 409, in run\n    yield self.execute_normal_sql(sql) + (sql, True, False)\n  File "/home/rpoole/.pyenv/versions/3.9.1/lib/python3.9/site-packages/pgcli/pgexecute.py", line 444, in execute_normal_sql\n    cur.execute(split_sql)\n  File "/home/rpoole/.pyenv/versions/3.9.1/lib/python3.9/site-packages/pgcli/pgexecute.py", line 39, in _wait_select\n    state = conn.poll()\npsycopg2.OperationalError: server closed the connection unexpectedly\n\tThis probably means the server terminated abnormally\n\tbefore or while processing the request.\n\n'
2021-06-15 17:29:03,987 (23366/MainThread) pgcli.main ERROR - sql: 'delete from dota_immortals_mintedplay; delete from dota_immortals_mintedpack; delete from dota_immortals_drop;', error: OperationalError('server closed the connection unexpectedly\n\tThis probably means the server terminated abnormally\n\tbefore or while processing the request.\n')
2021-06-15 17:29:03,989 (23366/MainThread) pgcli.main ERROR - traceback: 'Traceback (most recent call last):\n  File "/home/rpoole/.pyenv/versions/3.9.1/lib/python3.9/site-packages/pgcli/main.py", line 654, in execute_command\n    output, query = self._evaluate_command(text)\n  File "/home/rpoole/.pyenv/versions/3.9.1/lib/python3.9/site-packages/pgcli/main.py", line 901, in _evaluate_command\n    for title, cur, headers, status, sql, success, is_special in res:\n  File "/home/rpoole/.pyenv/versions/3.9.1/lib/python3.9/site-packages/pgcli/pgexecute.py", line 409, in run\n    yield self.execute_normal_sql(sql) + (sql, True, False)\n  File "/home/rpoole/.pyenv/versions/3.9.1/lib/python3.9/site-packages/pgcli/pgexecute.py", line 444, in execute_normal_sql\n    cur.execute(split_sql)\n  File "/home/rpoole/.pyenv/versions/3.9.1/lib/python3.9/site-packages/pgcli/pgexecute.py", line 39, in _wait_select\n    state = conn.poll()\npsycopg2.OperationalError: server closed the connection unexpectedly\n\tThis probably means the server terminated abnormally\n\tbefore or while processing the request.\n\n'
2021-06-16 16:38:13,309 (23366/MainThread) pgcli.pgexecute ERROR - sql: '\\l', error: OperationalError('server closed the connection unexpectedly\n\tThis probably means the server terminated abnormally\n\tbefore or while processing the request.\n')
2021-06-16 16:38:13,311 (23366/MainThread) pgcli.pgexecute ERROR - traceback: 'Traceback (most recent call last):\n  File "/home/rpoole/.pyenv/versions/3.9.1/lib/python3.9/site-packages/pgcli/pgexecute.py", line 398, in run\n    for result in pgspecial.execute(cur, sql):\n  File "/home/rpoole/.pyenv/versions/3.9.1/lib/python3.9/site-packages/pgspecial/main.py", line 117, in execute\n    return special_cmd.handler(cur=cur, pattern=pattern, verbose=verbose)\n  File "/home/rpoole/.pyenv/versions/3.9.1/lib/python3.9/site-packages/pgspecial/dbcommands.py", line 60, in list_databases\n    cur.execute(query)\n  File "/home/rpoole/.pyenv/versions/3.9.1/lib/python3.9/site-packages/pgcli/pgexecute.py", line 39, in _wait_select\n    state = conn.poll()\npsycopg2.OperationalError: server closed the connection unexpectedly\n\tThis probably means the server terminated abnormally\n\tbefore or while processing the request.\n\n'
2021-06-16 16:38:13,311 (23366/MainThread) pgcli.main ERROR - sql: '\\l', error: OperationalError('server closed the connection unexpectedly\n\tThis probably means the server terminated abnormally\n\tbefore or while processing the request.\n')
2021-06-16 16:38:13,311 (23366/MainThread) pgcli.main ERROR - traceback: 'Traceback (most recent call last):\n  File "/home/rpoole/.pyenv/versions/3.9.1/lib/python3.9/site-packages/pgcli/main.py", line 654, in execute_command\n    output, query = self._evaluate_command(text)\n  File "/home/rpoole/.pyenv/versions/3.9.1/lib/python3.9/site-packages/pgcli/main.py", line 901, in _evaluate_command\n    for title, cur, headers, status, sql, success, is_special in res:\n  File "/home/rpoole/.pyenv/versions/3.9.1/lib/python3.9/site-packages/pgcli/pgexecute.py", line 398, in run\n    for result in pgspecial.execute(cur, sql):\n  File "/home/rpoole/.pyenv/versions/3.9.1/lib/python3.9/site-packages/pgspecial/main.py", line 117, in execute\n    return special_cmd.handler(cur=cur, pattern=pattern, verbose=verbose)\n  File "/home/rpoole/.pyenv/versions/3.9.1/lib/python3.9/site-packages/pgspecial/dbcommands.py", line 60, in list_databases\n    cur.execute(query)\n  File "/home/rpoole/.pyenv/versions/3.9.1/lib/python3.9/site-packages/pgcli/pgexecute.py", line 39, in _wait_select\n    state = conn.poll()\npsycopg2.OperationalError: server closed the connection unexpectedly\n\tThis probably means the server terminated abnormally\n\tbefore or while processing the request.\n\n'
2021-06-16 16:38:33,573 (23366/MainThread) pgcli.pgexecute ERROR - sql: 'drop database dota_immortals', error: ObjectInUse('cannot drop the currently open database\n')
2021-06-16 16:38:33,574 (23366/MainThread) pgcli.pgexecute ERROR - traceback: 'Traceback (most recent call last):\n  File "/home/rpoole/.pyenv/versions/3.9.1/lib/python3.9/site-packages/pgcli/pgexecute.py", line 409, in run\n    yield self.execute_normal_sql(sql) + (sql, True, False)\n  File "/home/rpoole/.pyenv/versions/3.9.1/lib/python3.9/site-packages/pgcli/pgexecute.py", line 444, in execute_normal_sql\n    cur.execute(split_sql)\npsycopg2.errors.ObjectInUse: cannot drop the currently open database\n\n'
2021-06-16 16:40:57,213 (29102/MainThread) pgcli.main INFO - Default pager found in config file: "less -SRXF"
2021-06-16 16:42:19,221 (29102/MainThread) pgcli.pgexecute ERROR - sql: '\\dt', error: OperationalError('server closed the connection unexpectedly\n\tThis probably means the server terminated abnormally\n\tbefore or while processing the request.\n')
2021-06-16 16:42:19,221 (29102/MainThread) pgcli.pgexecute ERROR - traceback: 'Traceback (most recent call last):\n  File "/home/rpoole/.pyenv/versions/3.9.1/lib/python3.9/site-packages/pgcli/pgexecute.py", line 398, in run\n    for result in pgspecial.execute(cur, sql):\n  File "/home/rpoole/.pyenv/versions/3.9.1/lib/python3.9/site-packages/pgspecial/main.py", line 117, in execute\n    return special_cmd.handler(cur=cur, pattern=pattern, verbose=verbose)\n  File "/home/rpoole/.pyenv/versions/3.9.1/lib/python3.9/site-packages/pgspecial/dbcommands.py", line 419, in list_tables\n    return list_objects(cur, pattern, verbose, ["r", "p", ""])\n  File "/home/rpoole/.pyenv/versions/3.9.1/lib/python3.9/site-packages/pgspecial/dbcommands.py", line 410, in list_objects\n    cur.execute(sql)\n  File "/home/rpoole/.pyenv/versions/3.9.1/lib/python3.9/site-packages/pgcli/pgexecute.py", line 39, in _wait_select\n    state = conn.poll()\npsycopg2.OperationalError: server closed the connection unexpectedly\n\tThis probably means the server terminated abnormally\n\tbefore or while processing the request.\n\n'
2021-06-16 16:42:19,221 (29102/MainThread) pgcli.main ERROR - sql: '\\dt', error: OperationalError('server closed the connection unexpectedly\n\tThis probably means the server terminated abnormally\n\tbefore or while processing the request.\n')
2021-06-16 16:42:19,222 (29102/MainThread) pgcli.main ERROR - traceback: 'Traceback (most recent call last):\n  File "/home/rpoole/.pyenv/versions/3.9.1/lib/python3.9/site-packages/pgcli/main.py", line 654, in execute_command\n    output, query = self._evaluate_command(text)\n  File "/home/rpoole/.pyenv/versions/3.9.1/lib/python3.9/site-packages/pgcli/main.py", line 901, in _evaluate_command\n    for title, cur, headers, status, sql, success, is_special in res:\n  File "/home/rpoole/.pyenv/versions/3.9.1/lib/python3.9/site-packages/pgcli/pgexecute.py", line 398, in run\n    for result in pgspecial.execute(cur, sql):\n  File "/home/rpoole/.pyenv/versions/3.9.1/lib/python3.9/site-packages/pgspecial/main.py", line 117, in execute\n    return special_cmd.handler(cur=cur, pattern=pattern, verbose=verbose)\n  File "/home/rpoole/.pyenv/versions/3.9.1/lib/python3.9/site-packages/pgspecial/dbcommands.py", line 419, in list_tables\n    return list_objects(cur, pattern, verbose, ["r", "p", ""])\n  File "/home/rpoole/.pyenv/versions/3.9.1/lib/python3.9/site-packages/pgspecial/dbcommands.py", line 410, in list_objects\n    cur.execute(sql)\n  File "/home/rpoole/.pyenv/versions/3.9.1/lib/python3.9/site-packages/pgcli/pgexecute.py", line 39, in _wait_select\n    state = conn.poll()\npsycopg2.OperationalError: server closed the connection unexpectedly\n\tThis probably means the server terminated abnormally\n\tbefore or while processing the request.\n\n'
2021-06-16 16:46:22,151 (675/MainThread) pgcli.main INFO - Default pager found in config file: "less -SRXF"
2021-06-16 16:46:22,183 (675/MainThread) pgcli.main ERROR - traceback: 'Traceback (most recent call last):\n  File "/home/rpoole/.pyenv/versions/3.9.1/lib/python3.9/site-packages/pgcli/main.py", line 582, in connect\n    raise e\n  File "/home/rpoole/.pyenv/versions/3.9.1/lib/python3.9/site-packages/pgcli/main.py", line 569, in connect\n    pgexecute = PGExecute(database, user, passwd, host, port, dsn, **kwargs)\n  File "/home/rpoole/.pyenv/versions/3.9.1/lib/python3.9/site-packages/pgcli/pgexecute.py", line 214, in __init__\n    self.connect(database, user, password, host, port, dsn, **kwargs)\n  File "/home/rpoole/.pyenv/versions/3.9.1/lib/python3.9/site-packages/pgcli/pgexecute.py", line 254, in connect\n    conn = psycopg2.connect(**conn_params)\n  File "/home/rpoole/.pyenv/versions/3.9.1/lib/python3.9/site-packages/psycopg2/__init__.py", line 127, in connect\n    conn = _connect(dsn, connection_factory=connection_factory, **kwasync)\n  File "/home/rpoole/.pyenv/versions/3.9.1/lib/python3.9/site-packages/pgcli/pgexecute.py", line 39, in _wait_select\n    state = conn.poll()\npsycopg2.OperationalError: FATAL:  database "dota_immortals" does not exist\n\n'
2021-06-16 16:49:09,372 (3055/MainThread) pgcli.main INFO - Default pager found in config file: "less -SRXF"
2021-06-16 16:50:12,619 (4022/MainThread) pgcli.main INFO - Default pager found in config file: "less -SRXF"
2021-06-16 16:54:56,341 (6739/MainThread) pgcli.main INFO - Default pager found in config file: "less -SRXF"
2021-06-16 16:54:58,440 (6739/MainThread) pgcli.main ERROR - traceback: 'Traceback (most recent call last):\n  File "/home/rpoole/.pyenv/versions/3.9.1/lib/python3.9/site-packages/pgcli/main.py", line 569, in connect\n    pgexecute = PGExecute(database, user, passwd, host, port, dsn, **kwargs)\n  File "/home/rpoole/.pyenv/versions/3.9.1/lib/python3.9/site-packages/pgcli/pgexecute.py", line 214, in __init__\n    self.connect(database, user, password, host, port, dsn, **kwargs)\n  File "/home/rpoole/.pyenv/versions/3.9.1/lib/python3.9/site-packages/pgcli/pgexecute.py", line 254, in connect\n    conn = psycopg2.connect(**conn_params)\n  File "/home/rpoole/.pyenv/versions/3.9.1/lib/python3.9/site-packages/psycopg2/__init__.py", line 127, in connect\n    conn = _connect(dsn, connection_factory=connection_factory, **kwasync)\n  File "/home/rpoole/.pyenv/versions/3.9.1/lib/python3.9/site-packages/pgcli/pgexecute.py", line 39, in _wait_select\n    state = conn.poll()\npsycopg2.OperationalError: fe_sendauth: no password supplied\n\n\nDuring handling of the above exception, another exception occurred:\n\nTraceback (most recent call last):\n  File "/home/rpoole/.pyenv/versions/3.9.1/lib/python3.9/site-packages/pgcli/main.py", line 578, in connect\n    pgexecute = PGExecute(\n  File "/home/rpoole/.pyenv/versions/3.9.1/lib/python3.9/site-packages/pgcli/pgexecute.py", line 214, in __init__\n    self.connect(database, user, password, host, port, dsn, **kwargs)\n  File "/home/rpoole/.pyenv/versions/3.9.1/lib/python3.9/site-packages/pgcli/pgexecute.py", line 254, in connect\n    conn = psycopg2.connect(**conn_params)\n  File "/home/rpoole/.pyenv/versions/3.9.1/lib/python3.9/site-packages/psycopg2/__init__.py", line 127, in connect\n    conn = _connect(dsn, connection_factory=connection_factory, **kwasync)\n  File "/home/rpoole/.pyenv/versions/3.9.1/lib/python3.9/site-packages/pgcli/pgexecute.py", line 39, in _wait_select\n    state = conn.poll()\npsycopg2.OperationalError: FATAL:  password authentication failed for user "root"\n\n'
2021-06-16 16:54:59,905 (6843/MainThread) pgcli.main INFO - Default pager found in config file: "less -SRXF"
2021-06-16 16:55:02,306 (6843/MainThread) pgcli.main ERROR - traceback: 'Traceback (most recent call last):\n  File "/home/rpoole/.pyenv/versions/3.9.1/lib/python3.9/site-packages/pgcli/main.py", line 569, in connect\n    pgexecute = PGExecute(database, user, passwd, host, port, dsn, **kwargs)\n  File "/home/rpoole/.pyenv/versions/3.9.1/lib/python3.9/site-packages/pgcli/pgexecute.py", line 214, in __init__\n    self.connect(database, user, password, host, port, dsn, **kwargs)\n  File "/home/rpoole/.pyenv/versions/3.9.1/lib/python3.9/site-packages/pgcli/pgexecute.py", line 254, in connect\n    conn = psycopg2.connect(**conn_params)\n  File "/home/rpoole/.pyenv/versions/3.9.1/lib/python3.9/site-packages/psycopg2/__init__.py", line 127, in connect\n    conn = _connect(dsn, connection_factory=connection_factory, **kwasync)\n  File "/home/rpoole/.pyenv/versions/3.9.1/lib/python3.9/site-packages/pgcli/pgexecute.py", line 39, in _wait_select\n    state = conn.poll()\npsycopg2.OperationalError: fe_sendauth: no password supplied\n\n\nDuring handling of the above exception, another exception occurred:\n\nTraceback (most recent call last):\n  File "/home/rpoole/.pyenv/versions/3.9.1/lib/python3.9/site-packages/pgcli/main.py", line 578, in connect\n    pgexecute = PGExecute(\n  File "/home/rpoole/.pyenv/versions/3.9.1/lib/python3.9/site-packages/pgcli/pgexecute.py", line 214, in __init__\n    self.connect(database, user, password, host, port, dsn, **kwargs)\n  File "/home/rpoole/.pyenv/versions/3.9.1/lib/python3.9/site-packages/pgcli/pgexecute.py", line 254, in connect\n    conn = psycopg2.connect(**conn_params)\n  File "/home/rpoole/.pyenv/versions/3.9.1/lib/python3.9/site-packages/psycopg2/__init__.py", line 127, in connect\n    conn = _connect(dsn, connection_factory=connection_factory, **kwasync)\n  File "/home/rpoole/.pyenv/versions/3.9.1/lib/python3.9/site-packages/pgcli/pgexecute.py", line 39, in _wait_select\n    state = conn.poll()\npsycopg2.OperationalError: FATAL:  password authentication failed for user "root"\n\n'
2021-06-16 16:56:03,894 (7389/MainThread) pgcli.main INFO - Default pager found in config file: "less -SRXF"
2021-06-16 16:56:03,923 (7389/MainThread) pgcli.main ERROR - traceback: 'Traceback (most recent call last):\n  File "/home/rpoole/.pyenv/versions/3.9.1/lib/python3.9/site-packages/pgcli/main.py", line 582, in connect\n    raise e\n  File "/home/rpoole/.pyenv/versions/3.9.1/lib/python3.9/site-packages/pgcli/main.py", line 569, in connect\n    pgexecute = PGExecute(database, user, passwd, host, port, dsn, **kwargs)\n  File "/home/rpoole/.pyenv/versions/3.9.1/lib/python3.9/site-packages/pgcli/pgexecute.py", line 214, in __init__\n    self.connect(database, user, password, host, port, dsn, **kwargs)\n  File "/home/rpoole/.pyenv/versions/3.9.1/lib/python3.9/site-packages/pgcli/pgexecute.py", line 254, in connect\n    conn = psycopg2.connect(**conn_params)\n  File "/home/rpoole/.pyenv/versions/3.9.1/lib/python3.9/site-packages/psycopg2/__init__.py", line 127, in connect\n    conn = _connect(dsn, connection_factory=connection_factory, **kwasync)\n  File "/home/rpoole/.pyenv/versions/3.9.1/lib/python3.9/site-packages/pgcli/pgexecute.py", line 39, in _wait_select\n    state = conn.poll()\npsycopg2.OperationalError: FATAL:  database "dota_immortals" does not exist\n\n'
2021-06-16 16:56:10,513 (7493/MainThread) pgcli.main INFO - Default pager found in config file: "less -SRXF"
2021-06-16 16:56:12,403 (7493/MainThread) pgcli.main ERROR - traceback: 'Traceback (most recent call last):\n  File "/home/rpoole/.pyenv/versions/3.9.1/lib/python3.9/site-packages/pgcli/main.py", line 569, in connect\n    pgexecute = PGExecute(database, user, passwd, host, port, dsn, **kwargs)\n  File "/home/rpoole/.pyenv/versions/3.9.1/lib/python3.9/site-packages/pgcli/pgexecute.py", line 214, in __init__\n    self.connect(database, user, password, host, port, dsn, **kwargs)\n  File "/home/rpoole/.pyenv/versions/3.9.1/lib/python3.9/site-packages/pgcli/pgexecute.py", line 254, in connect\n    conn = psycopg2.connect(**conn_params)\n  File "/home/rpoole/.pyenv/versions/3.9.1/lib/python3.9/site-packages/psycopg2/__init__.py", line 127, in connect\n    conn = _connect(dsn, connection_factory=connection_factory, **kwasync)\n  File "/home/rpoole/.pyenv/versions/3.9.1/lib/python3.9/site-packages/pgcli/pgexecute.py", line 39, in _wait_select\n    state = conn.poll()\npsycopg2.OperationalError: fe_sendauth: no password supplied\n\n\nDuring handling of the above exception, another exception occurred:\n\nTraceback (most recent call last):\n  File "/home/rpoole/.pyenv/versions/3.9.1/lib/python3.9/site-packages/click/termui.py", line 129, in prompt_func\n    return f("")\n  File "/home/rpoole/.pyenv/versions/3.9.1/lib/python3.9/site-packages/click/termui.py", line 54, in hidden_prompt_func\n    return getpass.getpass(prompt)\n  File "/home/rpoole/.pyenv/versions/3.9.1/lib/python3.9/getpass.py", line 77, in unix_getpass\n    passwd = _raw_input(prompt, stream, input=input)\n  File "/home/rpoole/.pyenv/versions/3.9.1/lib/python3.9/getpass.py", line 146, in _raw_input\n    line = input.readline()\nKeyboardInterrupt\n\nDuring handling of the above exception, another exception occurred:\n\nTraceback (most recent call last):\n  File "/home/rpoole/.pyenv/versions/3.9.1/lib/python3.9/site-packages/pgcli/main.py", line 572, in connect\n    passwd = click.prompt(\n  File "/home/rpoole/.pyenv/versions/3.9.1/lib/python3.9/site-packages/click/termui.py", line 147, in prompt\n    value = prompt_func(prompt)\n  File "/home/rpoole/.pyenv/versions/3.9.1/lib/python3.9/site-packages/click/termui.py", line 136, in prompt_func\n    raise Abort()\nclick.exceptions.Abort\n'
2021-06-16 16:56:15,558 (7597/MainThread) pgcli.main INFO - Default pager found in config file: "less -SRXF"
2021-06-16 16:56:18,315 (7597/MainThread) pgcli.main ERROR - traceback: 'Traceback (most recent call last):\n  File "/home/rpoole/.pyenv/versions/3.9.1/lib/python3.9/site-packages/pgcli/main.py", line 569, in connect\n    pgexecute = PGExecute(database, user, passwd, host, port, dsn, **kwargs)\n  File "/home/rpoole/.pyenv/versions/3.9.1/lib/python3.9/site-packages/pgcli/pgexecute.py", line 214, in __init__\n    self.connect(database, user, password, host, port, dsn, **kwargs)\n  File "/home/rpoole/.pyenv/versions/3.9.1/lib/python3.9/site-packages/pgcli/pgexecute.py", line 254, in connect\n    conn = psycopg2.connect(**conn_params)\n  File "/home/rpoole/.pyenv/versions/3.9.1/lib/python3.9/site-packages/psycopg2/__init__.py", line 127, in connect\n    conn = _connect(dsn, connection_factory=connection_factory, **kwasync)\n  File "/home/rpoole/.pyenv/versions/3.9.1/lib/python3.9/site-packages/pgcli/pgexecute.py", line 39, in _wait_select\n    state = conn.poll()\npsycopg2.OperationalError: fe_sendauth: no password supplied\n\n\nDuring handling of the above exception, another exception occurred:\n\nTraceback (most recent call last):\n  File "/home/rpoole/.pyenv/versions/3.9.1/lib/python3.9/site-packages/pgcli/main.py", line 578, in connect\n    pgexecute = PGExecute(\n  File "/home/rpoole/.pyenv/versions/3.9.1/lib/python3.9/site-packages/pgcli/pgexecute.py", line 214, in __init__\n    self.connect(database, user, password, host, port, dsn, **kwargs)\n  File "/home/rpoole/.pyenv/versions/3.9.1/lib/python3.9/site-packages/pgcli/pgexecute.py", line 254, in connect\n    conn = psycopg2.connect(**conn_params)\n  File "/home/rpoole/.pyenv/versions/3.9.1/lib/python3.9/site-packages/psycopg2/__init__.py", line 127, in connect\n    conn = _connect(dsn, connection_factory=connection_factory, **kwasync)\n  File "/home/rpoole/.pyenv/versions/3.9.1/lib/python3.9/site-packages/pgcli/pgexecute.py", line 39, in _wait_select\n    state = conn.poll()\npsycopg2.OperationalError: FATAL:  database "root" does not exist\n\n'
2021-06-16 16:56:42,366 (8023/MainThread) pgcli.main INFO - Default pager found in config file: "less -SRXF"
2021-06-16 16:56:58,827 (8153/MainThread) pgcli.main INFO - Default pager found in config file: "less -SRXF"
2021-06-16 16:57:11,252 (8520/MainThread) pgcli.main INFO - Default pager found in config file: "less -SRXF"
2021-06-27 17:59:51,050 (1273/MainThread) pgcli.main INFO - Default pager found in config file: "less -SRXF"
2021-06-27 17:59:51,050 (1273/MainThread) pgcli.main WARNING - import keyring failed: ModuleNotFoundError("No module named 'keyring'").
2021-06-27 17:59:51,052 (1273/MainThread) pgcli.main ERROR - traceback: 'Traceback (most recent call last):\n  File "/home/rpoole/.pyenv/versions/3.9.1/lib/python3.9/site-packages/pgcli/main.py", line 582, in connect\n    raise e\n  File "/home/rpoole/.pyenv/versions/3.9.1/lib/python3.9/site-packages/pgcli/main.py", line 569, in connect\n    pgexecute = PGExecute(database, user, passwd, host, port, dsn, **kwargs)\n  File "/home/rpoole/.pyenv/versions/3.9.1/lib/python3.9/site-packages/pgcli/pgexecute.py", line 214, in __init__\n    self.connect(database, user, password, host, port, dsn, **kwargs)\n  File "/home/rpoole/.pyenv/versions/3.9.1/lib/python3.9/site-packages/pgcli/pgexecute.py", line 254, in connect\n    conn = psycopg2.connect(**conn_params)\n  File "/home/rpoole/.pyenv/versions/3.9.1/lib/python3.9/site-packages/psycopg2/__init__.py", line 122, in connect\n    conn = _connect(dsn, connection_factory=connection_factory, **kwasync)\npsycopg2.OperationalError: could not connect to server: No such file or directory\n\tIs the server running locally and accepting\n\tconnections on Unix domain socket "/var/run/postgresql/.s.PGSQL.5432"?\n\n'
2021-06-27 18:08:55,236 (4281/MainThread) pgcli.main INFO - Default pager found in config file: "less -SRXF"
2021-06-27 18:08:55,236 (4281/MainThread) pgcli.main WARNING - import keyring failed: ModuleNotFoundError("No module named 'keyring'").
2021-06-27 18:08:57,430 (4281/MainThread) pgcli.main ERROR - traceback: 'Traceback (most recent call last):\n  File "/home/rpoole/.pyenv/versions/3.9.1/lib/python3.9/site-packages/pgcli/main.py", line 569, in connect\n    pgexecute = PGExecute(database, user, passwd, host, port, dsn, **kwargs)\n  File "/home/rpoole/.pyenv/versions/3.9.1/lib/python3.9/site-packages/pgcli/pgexecute.py", line 214, in __init__\n    self.connect(database, user, password, host, port, dsn, **kwargs)\n  File "/home/rpoole/.pyenv/versions/3.9.1/lib/python3.9/site-packages/pgcli/pgexecute.py", line 254, in connect\n    conn = psycopg2.connect(**conn_params)\n  File "/home/rpoole/.pyenv/versions/3.9.1/lib/python3.9/site-packages/psycopg2/__init__.py", line 122, in connect\n    conn = _connect(dsn, connection_factory=connection_factory, **kwasync)\n  File "/home/rpoole/.pyenv/versions/3.9.1/lib/python3.9/site-packages/pgcli/pgexecute.py", line 39, in _wait_select\n    state = conn.poll()\npsycopg2.OperationalError: fe_sendauth: no password supplied\n\n\nDuring handling of the above exception, another exception occurred:\n\nTraceback (most recent call last):\n  File "/home/rpoole/.pyenv/versions/3.9.1/lib/python3.9/site-packages/click/termui.py", line 129, in prompt_func\n    return f("")\n  File "/home/rpoole/.pyenv/versions/3.9.1/lib/python3.9/site-packages/click/termui.py", line 54, in hidden_prompt_func\n    return getpass.getpass(prompt)\n  File "/home/rpoole/.pyenv/versions/3.9.1/lib/python3.9/getpass.py", line 77, in unix_getpass\n    passwd = _raw_input(prompt, stream, input=input)\n  File "/home/rpoole/.pyenv/versions/3.9.1/lib/python3.9/getpass.py", line 146, in _raw_input\n    line = input.readline()\nKeyboardInterrupt\n\nDuring handling of the above exception, another exception occurred:\n\nTraceback (most recent call last):\n  File "/home/rpoole/.pyenv/versions/3.9.1/lib/python3.9/site-packages/pgcli/main.py", line 572, in connect\n    passwd = click.prompt(\n  File "/home/rpoole/.pyenv/versions/3.9.1/lib/python3.9/site-packages/click/termui.py", line 147, in prompt\n    value = prompt_func(prompt)\n  File "/home/rpoole/.pyenv/versions/3.9.1/lib/python3.9/site-packages/click/termui.py", line 136, in prompt_func\n    raise Abort()\nclick.exceptions.Abort\n'
2021-06-27 18:09:21,999 (4518/MainThread) pgcli.main INFO - Default pager found in config file: "less -SRXF"
2021-06-27 18:09:21,999 (4518/MainThread) pgcli.main WARNING - import keyring failed: ModuleNotFoundError("No module named 'keyring'").
2021-06-27 18:14:43,068 (7176/MainThread) pgcli.main INFO - Default pager found in config file: "less -SRXF"
2021-06-27 18:14:43,068 (7176/MainThread) pgcli.main WARNING - import keyring failed: ModuleNotFoundError("No module named 'keyring'").
2021-06-28 18:23:45,545 (7176/MainThread) pgcli.pgexecute ERROR - sql: 'delete from dota_immortals_hero where id >= 13', error: OperationalError('server closed the connection unexpectedly\n\tThis probably means the server terminated abnormally\n\tbefore or while processing the request.\n')
2021-06-28 18:23:45,545 (7176/MainThread) pgcli.pgexecute ERROR - traceback: 'Traceback (most recent call last):\n  File "/home/rpoole/.pyenv/versions/3.9.1/lib/python3.9/site-packages/pgcli/pgexecute.py", line 409, in run\n    yield self.execute_normal_sql(sql) + (sql, True, False)\n  File "/home/rpoole/.pyenv/versions/3.9.1/lib/python3.9/site-packages/pgcli/pgexecute.py", line 444, in execute_normal_sql\n    cur.execute(split_sql)\n  File "/home/rpoole/.pyenv/versions/3.9.1/lib/python3.9/site-packages/pgcli/pgexecute.py", line 39, in _wait_select\n    state = conn.poll()\npsycopg2.OperationalError: server closed the connection unexpectedly\n\tThis probably means the server terminated abnormally\n\tbefore or while processing the request.\n\n'
2021-06-28 18:23:45,546 (7176/MainThread) pgcli.main ERROR - sql: 'delete from dota_immortals_hero where id >= 13;', error: OperationalError('server closed the connection unexpectedly\n\tThis probably means the server terminated abnormally\n\tbefore or while processing the request.\n')
2021-06-28 18:23:45,546 (7176/MainThread) pgcli.main ERROR - traceback: 'Traceback (most recent call last):\n  File "/home/rpoole/.pyenv/versions/3.9.1/lib/python3.9/site-packages/pgcli/main.py", line 654, in execute_command\n    output, query = self._evaluate_command(text)\n  File "/home/rpoole/.pyenv/versions/3.9.1/lib/python3.9/site-packages/pgcli/main.py", line 901, in _evaluate_command\n    for title, cur, headers, status, sql, success, is_special in res:\n  File "/home/rpoole/.pyenv/versions/3.9.1/lib/python3.9/site-packages/pgcli/pgexecute.py", line 409, in run\n    yield self.execute_normal_sql(sql) + (sql, True, False)\n  File "/home/rpoole/.pyenv/versions/3.9.1/lib/python3.9/site-packages/pgcli/pgexecute.py", line 444, in execute_normal_sql\n    cur.execute(split_sql)\n  File "/home/rpoole/.pyenv/versions/3.9.1/lib/python3.9/site-packages/pgcli/pgexecute.py", line 39, in _wait_select\n    state = conn.poll()\npsycopg2.OperationalError: server closed the connection unexpectedly\n\tThis probably means the server terminated abnormally\n\tbefore or while processing the request.\n\n'
2021-06-28 18:42:02,265 (7176/MainThread) pgcli.pgexecute ERROR - sql: 'select ingame_name, countryfrom dota_immortals_player', error: UndefinedColumn('column "ingame_name" does not exist\nLINE 1: select ingame_name, countryfrom dota_immortals_player\n               ^\n')
2021-06-28 18:42:02,265 (7176/MainThread) pgcli.pgexecute ERROR - traceback: 'Traceback (most recent call last):\n  File "/home/rpoole/.pyenv/versions/3.9.1/lib/python3.9/site-packages/pgcli/pgexecute.py", line 409, in run\n    yield self.execute_normal_sql(sql) + (sql, True, False)\n  File "/home/rpoole/.pyenv/versions/3.9.1/lib/python3.9/site-packages/pgcli/pgexecute.py", line 444, in execute_normal_sql\n    cur.execute(split_sql)\npsycopg2.errors.UndefinedColumn: column "ingame_name" does not exist\nLINE 1: select ingame_name, countryfrom dota_immortals_player\n               ^\n\n'
2021-06-28 19:07:47,666 (7176/MainThread) pgcli.pgexecute ERROR - sql: 'select * from dota_immortals_player where ingame_name ilike "miracle"', error: UndefinedColumn('column "miracle" does not exist\nLINE 1: ...from dota_immortals_player where ingame_name ilike "miracle"\n                                                              ^\n')
2021-06-28 19:07:47,666 (7176/MainThread) pgcli.pgexecute ERROR - traceback: 'Traceback (most recent call last):\n  File "/home/rpoole/.pyenv/versions/3.9.1/lib/python3.9/site-packages/pgcli/pgexecute.py", line 409, in run\n    yield self.execute_normal_sql(sql) + (sql, True, False)\n  File "/home/rpoole/.pyenv/versions/3.9.1/lib/python3.9/site-packages/pgcli/pgexecute.py", line 444, in execute_normal_sql\n    cur.execute(split_sql)\npsycopg2.errors.UndefinedColumn: column "miracle" does not exist\nLINE 1: ...from dota_immortals_player where ingame_name ilike "miracle"\n                                                              ^\n\n'
2021-06-28 19:07:52,831 (7176/MainThread) pgcli.pgexecute ERROR - sql: 'select * from dota_immortals_player where ingame_name ilike = "miracle"', error: SyntaxError('syntax error at or near "="\nLINE 1: ...rom dota_immortals_player where ingame_name ilike = "miracle...\n                                                             ^\n')
2021-06-28 19:07:52,831 (7176/MainThread) pgcli.pgexecute ERROR - traceback: 'Traceback (most recent call last):\n  File "/home/rpoole/.pyenv/versions/3.9.1/lib/python3.9/site-packages/pgcli/pgexecute.py", line 409, in run\n    yield self.execute_normal_sql(sql) + (sql, True, False)\n  File "/home/rpoole/.pyenv/versions/3.9.1/lib/python3.9/site-packages/pgcli/pgexecute.py", line 444, in execute_normal_sql\n    cur.execute(split_sql)\npsycopg2.errors.SyntaxError: syntax error at or near "="\nLINE 1: ...rom dota_immortals_player where ingame_name ilike = "miracle...\n                                                             ^\n\n'
2021-06-28 19:11:17,866 (7176/MainThread) pgcli.pgexecute ERROR - sql: "select * from where name like '%Ray%'", error: SyntaxError('syntax error at or near "where"\nLINE 1: select * from where name like \'%Ray%\'\n                      ^\n')
2021-06-28 19:11:17,866 (7176/MainThread) pgcli.pgexecute ERROR - traceback: 'Traceback (most recent call last):\n  File "/home/rpoole/.pyenv/versions/3.9.1/lib/python3.9/site-packages/pgcli/pgexecute.py", line 409, in run\n    yield self.execute_normal_sql(sql) + (sql, True, False)\n  File "/home/rpoole/.pyenv/versions/3.9.1/lib/python3.9/site-packages/pgcli/pgexecute.py", line 444, in execute_normal_sql\n    cur.execute(split_sql)\npsycopg2.errors.SyntaxError: syntax error at or near "where"\nLINE 1: select * from where name like \'%Ray%\'\n                      ^\n\n'
2021-06-28 19:11:34,543 (7176/MainThread) pgcli.pgexecute ERROR - sql: "select * from dota_immortals_player ingame name ilike '%alien%'", error: SyntaxError('syntax error at or near "name"\nLINE 1: select * from dota_immortals_player ingame name ilike \'%alie...\n                                                   ^\n')
2021-06-28 19:11:34,543 (7176/MainThread) pgcli.pgexecute ERROR - traceback: 'Traceback (most recent call last):\n  File "/home/rpoole/.pyenv/versions/3.9.1/lib/python3.9/site-packages/pgcli/pgexecute.py", line 409, in run\n    yield self.execute_normal_sql(sql) + (sql, True, False)\n  File "/home/rpoole/.pyenv/versions/3.9.1/lib/python3.9/site-packages/pgcli/pgexecute.py", line 444, in execute_normal_sql\n    cur.execute(split_sql)\npsycopg2.errors.SyntaxError: syntax error at or near "name"\nLINE 1: select * from dota_immortals_player ingame name ilike \'%alie...\n                                                   ^\n\n'
2021-06-28 19:11:41,617 (7176/MainThread) pgcli.pgexecute ERROR - sql: "select * from dota_immortals_player ingame_name ilike '%alien%'", error: SyntaxError('syntax error at or near "ilike"\nLINE 1: select * from dota_immortals_player ingame_name ilike \'%alie...\n                                                        ^\n')
2021-06-28 19:11:41,618 (7176/MainThread) pgcli.pgexecute ERROR - traceback: 'Traceback (most recent call last):\n  File "/home/rpoole/.pyenv/versions/3.9.1/lib/python3.9/site-packages/pgcli/pgexecute.py", line 409, in run\n    yield self.execute_normal_sql(sql) + (sql, True, False)\n  File "/home/rpoole/.pyenv/versions/3.9.1/lib/python3.9/site-packages/pgcli/pgexecute.py", line 444, in execute_normal_sql\n    cur.execute(split_sql)\npsycopg2.errors.SyntaxError: syntax error at or near "ilike"\nLINE 1: select * from dota_immortals_player ingame_name ilike \'%alie...\n                                                        ^\n\n'
2021-06-29 17:55:29,472 (2529/MainThread) pgcli.main INFO - Default pager found in config file: "less -SRXF"
2021-06-29 17:55:29,473 (2529/MainThread) pgcli.main WARNING - import keyring failed: ModuleNotFoundError("No module named 'keyring'").
2021-06-29 18:01:08,080 (5967/MainThread) pgcli.main INFO - Default pager found in config file: "less -SRXF"
2021-06-29 18:01:08,080 (5967/MainThread) pgcli.main WARNING - import keyring failed: ModuleNotFoundError("No module named 'keyring'").
2021-06-29 18:01:08,085 (5967/MainThread) pgcli.main ERROR - traceback: 'Traceback (most recent call last):\n  File "/home/rpoole/.pyenv/versions/3.9.1/lib/python3.9/site-packages/pgcli/main.py", line 582, in connect\n    raise e\n  File "/home/rpoole/.pyenv/versions/3.9.1/lib/python3.9/site-packages/pgcli/main.py", line 569, in connect\n    pgexecute = PGExecute(database, user, passwd, host, port, dsn, **kwargs)\n  File "/home/rpoole/.pyenv/versions/3.9.1/lib/python3.9/site-packages/pgcli/pgexecute.py", line 214, in __init__\n    self.connect(database, user, password, host, port, dsn, **kwargs)\n  File "/home/rpoole/.pyenv/versions/3.9.1/lib/python3.9/site-packages/pgcli/pgexecute.py", line 254, in connect\n    conn = psycopg2.connect(**conn_params)\n  File "/home/rpoole/.pyenv/versions/3.9.1/lib/python3.9/site-packages/psycopg2/__init__.py", line 122, in connect\n    conn = _connect(dsn, connection_factory=connection_factory, **kwasync)\npsycopg2.OperationalError: could not connect to server: No such file or directory\n\tIs the server running locally and accepting\n\tconnections on Unix domain socket "/var/run/postgresql/.s.PGSQL.5432"?\n\n'
2021-06-29 18:16:08,769 (11765/MainThread) pgcli.main INFO - Default pager found in config file: "less -SRXF"
2021-06-29 18:16:08,769 (11765/MainThread) pgcli.main WARNING - import keyring failed: ModuleNotFoundError("No module named 'keyring'").
2021-06-29 19:28:47,725 (11765/MainThread) pgcli.pgexecute ERROR - sql: 'selete from dota_immortals_play where id >= 16', error: SyntaxError('syntax error at or near "selete"\nLINE 1: selete from dota_immortals_play where id >= 16\n        ^\n')
2021-06-29 19:28:47,726 (11765/MainThread) pgcli.pgexecute ERROR - traceback: 'Traceback (most recent call last):\n  File "/home/rpoole/.pyenv/versions/3.9.1/lib/python3.9/site-packages/pgcli/pgexecute.py", line 409, in run\n    yield self.execute_normal_sql(sql) + (sql, True, False)\n  File "/home/rpoole/.pyenv/versions/3.9.1/lib/python3.9/site-packages/pgcli/pgexecute.py", line 444, in execute_normal_sql\n    cur.execute(split_sql)\npsycopg2.errors.SyntaxError: syntax error at or near "selete"\nLINE 1: selete from dota_immortals_play where id >= 16\n        ^\n\n'
2021-06-29 22:07:04,559 (11765/MainThread) pgcli.pgexecute ERROR - sql: 'delete from dota_immortals_play where id >= 16', error: ForeignKeyViolation('update or delete on table "dota_immortals_play" violates foreign key constraint "dota_immortals_playc_play_id_e1517d81_fk_dota_immo" on table "dota_immortals_playcaster"\nDETAIL:  Key (id)=(25) is still referenced from table "dota_immortals_playcaster".\n')
2021-06-29 22:07:04,559 (11765/MainThread) pgcli.pgexecute ERROR - traceback: 'Traceback (most recent call last):\n  File "/home/rpoole/.pyenv/versions/3.9.1/lib/python3.9/site-packages/pgcli/pgexecute.py", line 409, in run\n    yield self.execute_normal_sql(sql) + (sql, True, False)\n  File "/home/rpoole/.pyenv/versions/3.9.1/lib/python3.9/site-packages/pgcli/pgexecute.py", line 444, in execute_normal_sql\n    cur.execute(split_sql)\npsycopg2.errors.ForeignKeyViolation: update or delete on table "dota_immortals_play" violates foreign key constraint "dota_immortals_playc_play_id_e1517d81_fk_dota_immo" on table "dota_immortals_playcaster"\nDETAIL:  Key (id)=(25) is still referenced from table "dota_immortals_playcaster".\n\n'
2021-06-29 22:07:34,158 (11765/MainThread) pgcli.pgexecute ERROR - sql: 'delete from dota_immortals_play where id >= 16', error: ForeignKeyViolation('update or delete on table "dota_immortals_play" violates foreign key constraint "dota_immortals_plays_play_id_1d9c0d31_fk_dota_immo" on table "dota_immortals_playsecondaryhero"\nDETAIL:  Key (id)=(25) is still referenced from table "dota_immortals_playsecondaryhero".\n')
2021-06-29 22:07:34,158 (11765/MainThread) pgcli.pgexecute ERROR - traceback: 'Traceback (most recent call last):\n  File "/home/rpoole/.pyenv/versions/3.9.1/lib/python3.9/site-packages/pgcli/pgexecute.py", line 409, in run\n    yield self.execute_normal_sql(sql) + (sql, True, False)\n  File "/home/rpoole/.pyenv/versions/3.9.1/lib/python3.9/site-packages/pgcli/pgexecute.py", line 444, in execute_normal_sql\n    cur.execute(split_sql)\npsycopg2.errors.ForeignKeyViolation: update or delete on table "dota_immortals_play" violates foreign key constraint "dota_immortals_plays_play_id_1d9c0d31_fk_dota_immo" on table "dota_immortals_playsecondaryhero"\nDETAIL:  Key (id)=(25) is still referenced from table "dota_immortals_playsecondaryhero".\n\n'
2021-06-29 22:07:49,246 (11765/MainThread) pgcli.pgexecute ERROR - sql: 'delete from dota_immortals_play where id >= 16', error: ForeignKeyViolation('update or delete on table "dota_immortals_play" violates foreign key constraint "dota_immortals_playt_play_id_dfdfbb36_fk_dota_immo" on table "dota_immortals_playteam"\nDETAIL:  Key (id)=(25) is still referenced from table "dota_immortals_playteam".\n')
2021-06-29 22:07:49,247 (11765/MainThread) pgcli.pgexecute ERROR - traceback: 'Traceback (most recent call last):\n  File "/home/rpoole/.pyenv/versions/3.9.1/lib/python3.9/site-packages/pgcli/pgexecute.py", line 409, in run\n    yield self.execute_normal_sql(sql) + (sql, True, False)\n  File "/home/rpoole/.pyenv/versions/3.9.1/lib/python3.9/site-packages/pgcli/pgexecute.py", line 444, in execute_normal_sql\n    cur.execute(split_sql)\npsycopg2.errors.ForeignKeyViolation: update or delete on table "dota_immortals_play" violates foreign key constraint "dota_immortals_playt_play_id_dfdfbb36_fk_dota_immo" on table "dota_immortals_playteam"\nDETAIL:  Key (id)=(25) is still referenced from table "dota_immortals_playteam".\n\n'
2021-06-30 10:19:17,726 (17902/MainThread) pgcli.main INFO - Default pager found in config file: "less -SRXF"
2021-06-30 10:19:17,726 (17902/MainThread) pgcli.main WARNING - import keyring failed: ModuleNotFoundError("No module named 'keyring'").
2021-06-30 17:34:42,429 (11765/MainThread) pgcli.pgexecute ERROR - sql: '\\d dota_immortals_mintedpack', error: OperationalError('server closed the connection unexpectedly\n\tThis probably means the server terminated abnormally\n\tbefore or while processing the request.\n')
2021-06-30 17:34:42,438 (11765/MainThread) pgcli.pgexecute ERROR - traceback: 'Traceback (most recent call last):\n  File "/home/rpoole/.pyenv/versions/3.9.1/lib/python3.9/site-packages/pgcli/pgexecute.py", line 398, in run\n    for result in pgspecial.execute(cur, sql):\n  File "/home/rpoole/.pyenv/versions/3.9.1/lib/python3.9/site-packages/pgspecial/main.py", line 117, in execute\n    return special_cmd.handler(cur=cur, pattern=pattern, verbose=verbose)\n  File "/home/rpoole/.pyenv/versions/3.9.1/lib/python3.9/site-packages/pgspecial/dbcommands.py", line 882, in describe_table_details\n    cur.execute(sql)\n  File "/home/rpoole/.pyenv/versions/3.9.1/lib/python3.9/site-packages/pgcli/pgexecute.py", line 39, in _wait_select\n    state = conn.poll()\npsycopg2.OperationalError: server closed the connection unexpectedly\n\tThis probably means the server terminated abnormally\n\tbefore or while processing the request.\n\n'
2021-06-30 17:34:42,438 (11765/MainThread) pgcli.main ERROR - sql: '\\d dota_immortals_mintedpack', error: OperationalError('server closed the connection unexpectedly\n\tThis probably means the server terminated abnormally\n\tbefore or while processing the request.\n')
2021-06-30 17:34:42,438 (11765/MainThread) pgcli.main ERROR - traceback: 'Traceback (most recent call last):\n  File "/home/rpoole/.pyenv/versions/3.9.1/lib/python3.9/site-packages/pgcli/main.py", line 654, in execute_command\n    output, query = self._evaluate_command(text)\n  File "/home/rpoole/.pyenv/versions/3.9.1/lib/python3.9/site-packages/pgcli/main.py", line 901, in _evaluate_command\n    for title, cur, headers, status, sql, success, is_special in res:\n  File "/home/rpoole/.pyenv/versions/3.9.1/lib/python3.9/site-packages/pgcli/pgexecute.py", line 398, in run\n    for result in pgspecial.execute(cur, sql):\n  File "/home/rpoole/.pyenv/versions/3.9.1/lib/python3.9/site-packages/pgspecial/main.py", line 117, in execute\n    return special_cmd.handler(cur=cur, pattern=pattern, verbose=verbose)\n  File "/home/rpoole/.pyenv/versions/3.9.1/lib/python3.9/site-packages/pgspecial/dbcommands.py", line 882, in describe_table_details\n    cur.execute(sql)\n  File "/home/rpoole/.pyenv/versions/3.9.1/lib/python3.9/site-packages/pgcli/pgexecute.py", line 39, in _wait_select\n    state = conn.poll()\npsycopg2.OperationalError: server closed the connection unexpectedly\n\tThis probably means the server terminated abnormally\n\tbefore or while processing the request.\n\n'
2021-07-01 16:50:12,845 (9111/MainThread) pgcli.main INFO - Default pager found in config file: "less -SRXF"
2021-07-01 16:50:12,845 (9111/MainThread) pgcli.main WARNING - import keyring failed: ModuleNotFoundError("No module named 'keyring'").
2021-07-02 16:04:39,463 (9111/MainThread) pgcli.pgexecute ERROR - sql: 'select * from dota_immortals_mintedplay join dota_immortals_mintedpack ON dota_immortals_mintedpack.id = dota_immortals_mintedplay.minted_pack_id join dota_immortals_pack ON dota_immortals_pack.id = dota_immortals_mintedpack.pack_id where dota_immortals_minted_pack.id = 2', error: UndefinedTable('missing FROM-clause entry for table "dota_immortals_minted_pack"\nLINE 1: ...pack.id = dota_immortals_mintedpack.pack_id where dota_immor...\n                                                             ^\n')
2021-07-02 16:04:39,471 (9111/MainThread) pgcli.pgexecute ERROR - traceback: 'Traceback (most recent call last):\n  File "/home/rpoole/.pyenv/versions/3.9.1/lib/python3.9/site-packages/pgcli/pgexecute.py", line 409, in run\n    yield self.execute_normal_sql(sql) + (sql, True, False)\n  File "/home/rpoole/.pyenv/versions/3.9.1/lib/python3.9/site-packages/pgcli/pgexecute.py", line 444, in execute_normal_sql\n    cur.execute(split_sql)\npsycopg2.errors.UndefinedTable: missing FROM-clause entry for table "dota_immortals_minted_pack"\nLINE 1: ...pack.id = dota_immortals_mintedpack.pack_id where dota_immor...\n                                                             ^\n\n'
2021-07-02 16:04:54,127 (29651/MainThread) pgcli.main INFO - Default pager found in config file: "less -SRXF"
2021-07-02 16:04:54,127 (29651/MainThread) pgcli.main WARNING - import keyring failed: ModuleNotFoundError("No module named 'keyring'").
2021-07-02 16:04:58,226 (29741/MainThread) pgcli.main INFO - Default pager found in config file: "less -SRXF"
2021-07-02 16:04:58,226 (29741/MainThread) pgcli.main WARNING - import keyring failed: ModuleNotFoundError("No module named 'keyring'").
2021-07-02 16:05:06,521 (29854/MainThread) pgcli.main INFO - Default pager found in config file: "less -SRXF"
2021-07-02 16:05:06,522 (29854/MainThread) pgcli.main WARNING - import keyring failed: ModuleNotFoundError("No module named 'keyring'").
2021-07-02 16:05:37,240 (29854/MainThread) pgcli.pgexecute ERROR - sql: 'select * from dota_immortals_mintedplay join dota_immortals_mintedpack ON dota_immortals_mintedpack.id = dota_immortals_mintedplay.minted_pack_id join dota_immortals_pack ON dota_immortals_pack.id = dota_immortals_mintedpack.pack_id where dota_immortals_minted_pack.id = 2', error: UndefinedTable('missing FROM-clause entry for table "dota_immortals_minted_pack"\nLINE 1: ...pack.id = dota_immortals_mintedpack.pack_id where dota_immor...\n                                                             ^\n')
2021-07-02 16:05:37,241 (29854/MainThread) pgcli.pgexecute ERROR - traceback: 'Traceback (most recent call last):\n  File "/home/rpoole/.pyenv/versions/3.9.1/lib/python3.9/site-packages/pgcli/pgexecute.py", line 409, in run\n    yield self.execute_normal_sql(sql) + (sql, True, False)\n  File "/home/rpoole/.pyenv/versions/3.9.1/lib/python3.9/site-packages/pgcli/pgexecute.py", line 444, in execute_normal_sql\n    cur.execute(split_sql)\npsycopg2.errors.UndefinedTable: missing FROM-clause entry for table "dota_immortals_minted_pack"\nLINE 1: ...pack.id = dota_immortals_mintedpack.pack_id where dota_immor...\n                                                             ^\n\n'
2021-07-02 16:15:46,348 (29854/MainThread) pgcli.pgexecute ERROR - sql: 'select distinct(dota_immortals_play.id) from dota_immortals_play join dota_immortals_mintedplay ON dota_immortals_mintedplay.play_id = dota_immortals_play.id join dota_immortals_mintedpack ON dota_immortals_mintedpack.id = dota_immortals_mintedplay.minted_pack_id where dota_immortals_minted_pack.pack_id = 3', error: UndefinedTable('missing FROM-clause entry for table "dota_immortals_minted_pack"\nLINE 1: ... = dota_immortals_mintedplay.minted_pack_id where dota_immor...\n                                                             ^\n')
2021-07-02 16:15:46,348 (29854/MainThread) pgcli.pgexecute ERROR - traceback: 'Traceback (most recent call last):\n  File "/home/rpoole/.pyenv/versions/3.9.1/lib/python3.9/site-packages/pgcli/pgexecute.py", line 409, in run\n    yield self.execute_normal_sql(sql) + (sql, True, False)\n  File "/home/rpoole/.pyenv/versions/3.9.1/lib/python3.9/site-packages/pgcli/pgexecute.py", line 444, in execute_normal_sql\n    cur.execute(split_sql)\npsycopg2.errors.UndefinedTable: missing FROM-clause entry for table "dota_immortals_minted_pack"\nLINE 1: ... = dota_immortals_mintedplay.minted_pack_id where dota_immor...\n                                                             ^\n\n'
2021-07-02 18:34:57,843 (11567/MainThread) pgcli.main INFO - Default pager found in config file: "less -SRXF"
2021-07-02 18:34:57,843 (11567/MainThread) pgcli.main WARNING - import keyring failed: ModuleNotFoundError("No module named 'keyring'").
2021-07-02 19:26:52,866 (17648/MainThread) pgcli.main INFO - Default pager found in config file: "less -SRXF"
2021-07-02 19:26:52,866 (17648/MainThread) pgcli.main WARNING - import keyring failed: ModuleNotFoundError("No module named 'keyring'").
2021-07-02 19:33:05,882 (11567/MainThread) pgcli.pgexecute ERROR - sql: 'create unique INDEX minted_play_sold_unique ON dota_immortals_mintedplaysale where (sold is false)', error: SyntaxError('syntax error at or near "where"\nLINE 1: ...play_sold_unique ON dota_immortals_mintedplaysale where (sol...\n                                                             ^\n')
2021-07-02 19:33:05,882 (11567/MainThread) pgcli.pgexecute ERROR - traceback: 'Traceback (most recent call last):\n  File "/home/rpoole/.pyenv/versions/3.9.1/lib/python3.9/site-packages/pgcli/pgexecute.py", line 409, in run\n    yield self.execute_normal_sql(sql) + (sql, True, False)\n  File "/home/rpoole/.pyenv/versions/3.9.1/lib/python3.9/site-packages/pgcli/pgexecute.py", line 444, in execute_normal_sql\n    cur.execute(split_sql)\npsycopg2.errors.SyntaxError: syntax error at or near "where"\nLINE 1: ...play_sold_unique ON dota_immortals_mintedplaysale where (sol...\n                                                             ^\n\n'
2021-07-02 19:34:22,753 (11567/MainThread) pgcli.pgexecute ERROR - sql: 'update dota_immortals_mintedplaysale set sold = False where id = 1', error: UniqueViolation('duplicate key value violates unique constraint "minted_play_sold_unique"\nDETAIL:  Key (minted_play_id)=(1838) already exists.\n')
2021-07-02 19:34:22,753 (11567/MainThread) pgcli.pgexecute ERROR - traceback: 'Traceback (most recent call last):\n  File "/home/rpoole/.pyenv/versions/3.9.1/lib/python3.9/site-packages/pgcli/pgexecute.py", line 409, in run\n    yield self.execute_normal_sql(sql) + (sql, True, False)\n  File "/home/rpoole/.pyenv/versions/3.9.1/lib/python3.9/site-packages/pgcli/pgexecute.py", line 444, in execute_normal_sql\n    cur.execute(split_sql)\npsycopg2.errors.UniqueViolation: duplicate key value violates unique constraint "minted_play_sold_unique"\nDETAIL:  Key (minted_play_id)=(1838) already exists.\n\n'
2021-07-02 19:34:45,433 (11567/MainThread) pgcli.pgexecute ERROR - sql: 'drop INDEX minted_play_sold_unique ON dota_immortals_mintedplaysale', error: SyntaxError('syntax error at or near "ON"\nLINE 1: drop INDEX minted_play_sold_unique ON dota_immortals_mintedp...\n                                           ^\n')
2021-07-02 19:34:45,433 (11567/MainThread) pgcli.pgexecute ERROR - traceback: 'Traceback (most recent call last):\n  File "/home/rpoole/.pyenv/versions/3.9.1/lib/python3.9/site-packages/pgcli/pgexecute.py", line 409, in run\n    yield self.execute_normal_sql(sql) + (sql, True, False)\n  File "/home/rpoole/.pyenv/versions/3.9.1/lib/python3.9/site-packages/pgcli/pgexecute.py", line 444, in execute_normal_sql\n    cur.execute(split_sql)\npsycopg2.errors.SyntaxError: syntax error at or near "ON"\nLINE 1: drop INDEX minted_play_sold_unique ON dota_immortals_mintedp...\n                                           ^\n\n'
2021-07-03 13:07:09,079 (23561/MainThread) pgcli.main INFO - Default pager found in config file: "less -SRXF"
2021-07-03 13:07:09,079 (23561/MainThread) pgcli.main WARNING - import keyring failed: ModuleNotFoundError("No module named 'keyring'").
2021-07-03 13:07:45,009 (23561/MainThread) pgcli.pgexecute ERROR - sql: 'select * from dota_immortals_mintedplaysale for update skip locked where id = 1 and sold = false', error: SyntaxError('syntax error at or near "where"\nLINE 1: ...a_immortals_mintedplaysale for update skip locked where id =...\n                                                             ^\n')
2021-07-03 13:07:45,010 (23561/MainThread) pgcli.pgexecute ERROR - traceback: 'Traceback (most recent call last):\n  File "/home/rpoole/.pyenv/versions/3.9.1/lib/python3.9/site-packages/pgcli/pgexecute.py", line 409, in run\n    yield self.execute_normal_sql(sql) + (sql, True, False)\n  File "/home/rpoole/.pyenv/versions/3.9.1/lib/python3.9/site-packages/pgcli/pgexecute.py", line 444, in execute_normal_sql\n    cur.execute(split_sql)\npsycopg2.errors.SyntaxError: syntax error at or near "where"\nLINE 1: ...a_immortals_mintedplaysale for update skip locked where id =...\n                                                             ^\n\n'
2021-07-03 13:07:54,165 (23561/MainThread) pgcli.pgexecute ERROR - sql: 'select * from dota_immortals_mintedplaysale where id = 1 and sold = false for update skip locked', error: InFailedSqlTransaction('current transaction is aborted, commands ignored until end of transaction block\n')
2021-07-03 13:07:54,165 (23561/MainThread) pgcli.pgexecute ERROR - traceback: 'Traceback (most recent call last):\n  File "/home/rpoole/.pyenv/versions/3.9.1/lib/python3.9/site-packages/pgcli/pgexecute.py", line 409, in run\n    yield self.execute_normal_sql(sql) + (sql, True, False)\n  File "/home/rpoole/.pyenv/versions/3.9.1/lib/python3.9/site-packages/pgcli/pgexecute.py", line 444, in execute_normal_sql\n    cur.execute(split_sql)\npsycopg2.errors.InFailedSqlTransaction: current transaction is aborted, commands ignored until end of transaction block\n\n'
2021-07-03 13:08:00,215 (23561/MainThread) pgcli.pgexecute ERROR - sql: 'begin', error: InFailedSqlTransaction('current transaction is aborted, commands ignored until end of transaction block\n')
2021-07-03 13:08:00,215 (23561/MainThread) pgcli.pgexecute ERROR - traceback: 'Traceback (most recent call last):\n  File "/home/rpoole/.pyenv/versions/3.9.1/lib/python3.9/site-packages/pgcli/pgexecute.py", line 409, in run\n    yield self.execute_normal_sql(sql) + (sql, True, False)\n  File "/home/rpoole/.pyenv/versions/3.9.1/lib/python3.9/site-packages/pgcli/pgexecute.py", line 444, in execute_normal_sql\n    cur.execute(split_sql)\npsycopg2.errors.InFailedSqlTransaction: current transaction is aborted, commands ignored until end of transaction block\n\n'
2021-07-03 13:08:12,810 (23927/MainThread) pgcli.main INFO - Default pager found in config file: "less -SRXF"
2021-07-03 13:08:12,810 (23927/MainThread) pgcli.main WARNING - import keyring failed: ModuleNotFoundError("No module named 'keyring'").
2021-07-03 13:15:11,842 (23927/MainThread) pgcli.pgexecute ERROR - sql: 'update dota_immortals_mintedplaysale set sold = false', error: UniqueViolation('duplicate key value violates unique constraint "minted_play_sale_not_sold"\nDETAIL:  Key (minted_play_id)=(1838) already exists.\n')
2021-07-03 13:15:11,842 (23927/MainThread) pgcli.pgexecute ERROR - traceback: 'Traceback (most recent call last):\n  File "/home/rpoole/.pyenv/versions/3.9.1/lib/python3.9/site-packages/pgcli/pgexecute.py", line 409, in run\n    yield self.execute_normal_sql(sql) + (sql, True, False)\n  File "/home/rpoole/.pyenv/versions/3.9.1/lib/python3.9/site-packages/pgcli/pgexecute.py", line 444, in execute_normal_sql\n    cur.execute(split_sql)\npsycopg2.errors.UniqueViolation: duplicate key value violates unique constraint "minted_play_sale_not_sold"\nDETAIL:  Key (minted_play_id)=(1838) already exists.\n\n'
2021-07-03 16:59:55,338 (23927/MainThread) pgcli.pgexecute ERROR - sql: 'update dota_immortals_mintedplaysale set sold = false', error: UniqueViolation('duplicate key value violates unique constraint "minted_play_sale_not_sold"\nDETAIL:  Key (minted_play_id)=(1843) already exists.\n')
2021-07-03 16:59:55,338 (23927/MainThread) pgcli.pgexecute ERROR - traceback: 'Traceback (most recent call last):\n  File "/home/rpoole/.pyenv/versions/3.9.1/lib/python3.9/site-packages/pgcli/pgexecute.py", line 409, in run\n    yield self.execute_normal_sql(sql) + (sql, True, False)\n  File "/home/rpoole/.pyenv/versions/3.9.1/lib/python3.9/site-packages/pgcli/pgexecute.py", line 444, in execute_normal_sql\n    cur.execute(split_sql)\npsycopg2.errors.UniqueViolation: duplicate key value violates unique constraint "minted_play_sale_not_sold"\nDETAIL:  Key (minted_play_id)=(1843) already exists.\n\n'
2021-07-06 07:52:21,163 (23927/MainThread) pgcli.pgexecute ERROR - sql: 'update dota_immortals_mintedplay set user_id = null', error: OperationalError('server closed the connection unexpectedly\n\tThis probably means the server terminated abnormally\n\tbefore or while processing the request.\n')
2021-07-06 07:52:21,163 (23927/MainThread) pgcli.pgexecute ERROR - traceback: 'Traceback (most recent call last):\n  File "/home/rpoole/.pyenv/versions/3.9.1/lib/python3.9/site-packages/pgcli/pgexecute.py", line 409, in run\n    yield self.execute_normal_sql(sql) + (sql, True, False)\n  File "/home/rpoole/.pyenv/versions/3.9.1/lib/python3.9/site-packages/pgcli/pgexecute.py", line 444, in execute_normal_sql\n    cur.execute(split_sql)\n  File "/home/rpoole/.pyenv/versions/3.9.1/lib/python3.9/site-packages/pgcli/pgexecute.py", line 39, in _wait_select\n    state = conn.poll()\npsycopg2.OperationalError: server closed the connection unexpectedly\n\tThis probably means the server terminated abnormally\n\tbefore or while processing the request.\n\n'
2021-07-06 07:52:21,164 (23927/MainThread) pgcli.main ERROR - sql: 'update dota_immortals_mintedplay set user_id = null;', error: OperationalError('server closed the connection unexpectedly\n\tThis probably means the server terminated abnormally\n\tbefore or while processing the request.\n')
2021-07-06 07:52:21,166 (23927/MainThread) pgcli.main ERROR - traceback: 'Traceback (most recent call last):\n  File "/home/rpoole/.pyenv/versions/3.9.1/lib/python3.9/site-packages/pgcli/main.py", line 654, in execute_command\n    output, query = self._evaluate_command(text)\n  File "/home/rpoole/.pyenv/versions/3.9.1/lib/python3.9/site-packages/pgcli/main.py", line 901, in _evaluate_command\n    for title, cur, headers, status, sql, success, is_special in res:\n  File "/home/rpoole/.pyenv/versions/3.9.1/lib/python3.9/site-packages/pgcli/pgexecute.py", line 409, in run\n    yield self.execute_normal_sql(sql) + (sql, True, False)\n  File "/home/rpoole/.pyenv/versions/3.9.1/lib/python3.9/site-packages/pgcli/pgexecute.py", line 444, in execute_normal_sql\n    cur.execute(split_sql)\n  File "/home/rpoole/.pyenv/versions/3.9.1/lib/python3.9/site-packages/pgcli/pgexecute.py", line 39, in _wait_select\n    state = conn.poll()\npsycopg2.OperationalError: server closed the connection unexpectedly\n\tThis probably means the server terminated abnormally\n\tbefore or while processing the request.\n\n'
2021-07-09 16:57:53,995 (15935/MainThread) pgcli.main INFO - Default pager found in config file: "less -SRXF"
2021-07-09 16:57:53,996 (15935/MainThread) pgcli.main WARNING - import keyring failed: ModuleNotFoundError("No module named 'keyring'").
2021-07-13 17:33:41,399 (25424/MainThread) pgcli.main INFO - Default pager found in config file: "less -SRXF"
2021-07-13 17:33:41,399 (25424/MainThread) pgcli.main WARNING - import keyring failed: ModuleNotFoundError("No module named 'keyring'").
2021-07-18 14:35:27,791 (11540/MainThread) pgcli.main INFO - Default pager found in config file: "less -SRXF"
2021-07-18 14:35:27,791 (11540/MainThread) pgcli.main WARNING - import keyring failed: ModuleNotFoundError("No module named 'keyring'").
2021-07-24 17:04:18,402 (11540/MainThread) pgcli.pgexecute ERROR - sql: 'update dota_immortals_pack set image_name = null', error: OperationalError('server closed the connection unexpectedly\n\tThis probably means the server terminated abnormally\n\tbefore or while processing the request.\n')
2021-07-24 17:04:18,405 (11540/MainThread) pgcli.pgexecute ERROR - traceback: 'Traceback (most recent call last):\n  File "/home/rpoole/.pyenv/versions/3.9.1/lib/python3.9/site-packages/pgcli/pgexecute.py", line 409, in run\n    yield self.execute_normal_sql(sql) + (sql, True, False)\n  File "/home/rpoole/.pyenv/versions/3.9.1/lib/python3.9/site-packages/pgcli/pgexecute.py", line 444, in execute_normal_sql\n    cur.execute(split_sql)\n  File "/home/rpoole/.pyenv/versions/3.9.1/lib/python3.9/site-packages/pgcli/pgexecute.py", line 39, in _wait_select\n    state = conn.poll()\npsycopg2.OperationalError: server closed the connection unexpectedly\n\tThis probably means the server terminated abnormally\n\tbefore or while processing the request.\n\n'
2021-07-24 17:04:18,406 (11540/MainThread) pgcli.main ERROR - sql: 'update dota_immortals_pack set image_name = null;', error: OperationalError('server closed the connection unexpectedly\n\tThis probably means the server terminated abnormally\n\tbefore or while processing the request.\n')
2021-07-24 17:04:18,407 (11540/MainThread) pgcli.main ERROR - traceback: 'Traceback (most recent call last):\n  File "/home/rpoole/.pyenv/versions/3.9.1/lib/python3.9/site-packages/pgcli/main.py", line 654, in execute_command\n    output, query = self._evaluate_command(text)\n  File "/home/rpoole/.pyenv/versions/3.9.1/lib/python3.9/site-packages/pgcli/main.py", line 901, in _evaluate_command\n    for title, cur, headers, status, sql, success, is_special in res:\n  File "/home/rpoole/.pyenv/versions/3.9.1/lib/python3.9/site-packages/pgcli/pgexecute.py", line 409, in run\n    yield self.execute_normal_sql(sql) + (sql, True, False)\n  File "/home/rpoole/.pyenv/versions/3.9.1/lib/python3.9/site-packages/pgcli/pgexecute.py", line 444, in execute_normal_sql\n    cur.execute(split_sql)\n  File "/home/rpoole/.pyenv/versions/3.9.1/lib/python3.9/site-packages/pgcli/pgexecute.py", line 39, in _wait_select\n    state = conn.poll()\npsycopg2.OperationalError: server closed the connection unexpectedly\n\tThis probably means the server terminated abnormally\n\tbefore or while processing the request.\n\n'
2021-07-24 17:04:18,422 (11540/MainThread) pgcli.pgexecute ERROR - sql: 'update dota_immortals_pack set image_name = null', error: NotNullViolation('null value in column "image_name" violates not-null constraint\nDETAIL:  Failing row contains (2, 2021-05-16 18:15:24.04893+00, 2021-05-20 20:38:45.681176+00, pack 2, 12.00, default description\r\nmore\r\n\r\nmore\r\nmoore ore\r\nasdf, null).\n')
2021-07-24 17:04:18,422 (11540/MainThread) pgcli.pgexecute ERROR - traceback: 'Traceback (most recent call last):\n  File "/home/rpoole/.pyenv/versions/3.9.1/lib/python3.9/site-packages/pgcli/main.py", line 654, in execute_command\n    output, query = self._evaluate_command(text)\n  File "/home/rpoole/.pyenv/versions/3.9.1/lib/python3.9/site-packages/pgcli/main.py", line 901, in _evaluate_command\n    for title, cur, headers, status, sql, success, is_special in res:\n  File "/home/rpoole/.pyenv/versions/3.9.1/lib/python3.9/site-packages/pgcli/pgexecute.py", line 409, in run\n    yield self.execute_normal_sql(sql) + (sql, True, False)\n  File "/home/rpoole/.pyenv/versions/3.9.1/lib/python3.9/site-packages/pgcli/pgexecute.py", line 444, in execute_normal_sql\n    cur.execute(split_sql)\n  File "/home/rpoole/.pyenv/versions/3.9.1/lib/python3.9/site-packages/pgcli/pgexecute.py", line 39, in _wait_select\n    state = conn.poll()\npsycopg2.OperationalError: server closed the connection unexpectedly\n\tThis probably means the server terminated abnormally\n\tbefore or while processing the request.\n\n\nDuring handling of the above exception, another exception occurred:\n\nTraceback (most recent call last):\n  File "/home/rpoole/.pyenv/versions/3.9.1/lib/python3.9/site-packages/pgcli/pgexecute.py", line 409, in run\n    yield self.execute_normal_sql(sql) + (sql, True, False)\n  File "/home/rpoole/.pyenv/versions/3.9.1/lib/python3.9/site-packages/pgcli/pgexecute.py", line 444, in execute_normal_sql\n    cur.execute(split_sql)\npsycopg2.errors.NotNullViolation: null value in column "image_name" violates not-null constraint\nDETAIL:  Failing row contains (2, 2021-05-16 18:15:24.04893+00, 2021-05-20 20:38:45.681176+00, pack 2, 12.00, default description\r\nmore\r\n\r\nmore\r\nmoore ore\r\nasdf, null).\n\n'
2021-07-24 17:04:30,457 (11540/MainThread) pgcli.pgexecute ERROR - sql: 'update dota_immortals_pack set image_name = "pack_placeholder.png"', error: UndefinedColumn('column "pack_placeholder.png" does not exist\nLINE 1: update dota_immortals_pack set image_name = "pack_placeholde...\n                                                    ^\n')
2021-07-24 17:04:30,457 (11540/MainThread) pgcli.pgexecute ERROR - traceback: 'Traceback (most recent call last):\n  File "/home/rpoole/.pyenv/versions/3.9.1/lib/python3.9/site-packages/pgcli/pgexecute.py", line 409, in run\n    yield self.execute_normal_sql(sql) + (sql, True, False)\n  File "/home/rpoole/.pyenv/versions/3.9.1/lib/python3.9/site-packages/pgcli/pgexecute.py", line 444, in execute_normal_sql\n    cur.execute(split_sql)\npsycopg2.errors.UndefinedColumn: column "pack_placeholder.png" does not exist\nLINE 1: update dota_immortals_pack set image_name = "pack_placeholde...\n                                                    ^\n\n'
2021-08-01 12:41:53,418 (5568/MainThread) pgcli.main INFO - Default pager found in config file: "less -SRXF"
2021-08-01 12:41:53,418 (5568/MainThread) pgcli.main WARNING - import keyring failed: ModuleNotFoundError("No module named 'keyring'").
2021-08-01 14:57:40,380 (4061/MainThread) pgcli.main INFO - Default pager found in config file: "less -SRXF"
2021-08-01 14:57:40,380 (4061/MainThread) pgcli.main WARNING - import keyring failed: ModuleNotFoundError("No module named 'keyring'").
2021-08-01 16:15:23,316 (4061/MainThread) pgcli.pgexecute ERROR - sql: 'select * from dota_immortals_mintedplay where id 3609', error: SyntaxError('syntax error at or near "3609"\nLINE 1: select * from dota_immortals_mintedplay where id 3609\n                                                         ^\n')
2021-08-01 16:15:23,317 (4061/MainThread) pgcli.pgexecute ERROR - traceback: 'Traceback (most recent call last):\n  File "/home/rpoole/.pyenv/versions/3.9.1/lib/python3.9/site-packages/pgcli/pgexecute.py", line 409, in run\n    yield self.execute_normal_sql(sql) + (sql, True, False)\n  File "/home/rpoole/.pyenv/versions/3.9.1/lib/python3.9/site-packages/pgcli/pgexecute.py", line 444, in execute_normal_sql\n    cur.execute(split_sql)\npsycopg2.errors.SyntaxError: syntax error at or near "3609"\nLINE 1: select * from dota_immortals_mintedplay where id 3609\n                                                         ^\n\n'
2021-08-02 14:53:48,178 (9440/MainThread) pgcli.main INFO - Default pager found in config file: "less -SRXF"
2021-08-02 14:53:48,179 (9440/MainThread) pgcli.main WARNING - import keyring failed: ModuleNotFoundError("No module named 'keyring'").
2021-08-02 14:58:11,245 (9440/MainThread) pgcli.pgexecute ERROR - sql: '\\dl dota_immortals_mintedplaysale', error: SyntaxError('syntax error at or near "\\"\nLINE 1: \\dl dota_immortals_mintedplaysale\n        ^\n')
2021-08-02 14:58:11,245 (9440/MainThread) pgcli.pgexecute ERROR - traceback: 'Traceback (most recent call last):\n  File "/home/rpoole/.pyenv/versions/3.9.1/lib/python3.9/site-packages/pgcli/pgexecute.py", line 409, in run\n    yield self.execute_normal_sql(sql) + (sql, True, False)\n  File "/home/rpoole/.pyenv/versions/3.9.1/lib/python3.9/site-packages/pgcli/pgexecute.py", line 444, in execute_normal_sql\n    cur.execute(split_sql)\npsycopg2.errors.SyntaxError: syntax error at or near "\\"\nLINE 1: \\dl dota_immortals_mintedplaysale\n        ^\n\n'
2021-08-02 15:01:04,260 (9440/MainThread) pgcli.pgexecute ERROR - sql: 'insert into dota_immortals_mintedplaysale (created, modified, sale_price, minted_play_id, sold, canceled) values (NOW(), NOW(), 10, 3600, False, False)', error: UniqueViolation('duplicate key value violates unique constraint "minted_play_sale_not_sold"\nDETAIL:  Key (minted_play_id)=(3600) already exists.\n')
2021-08-02 15:01:04,260 (9440/MainThread) pgcli.pgexecute ERROR - traceback: 'Traceback (most recent call last):\n  File "/home/rpoole/.pyenv/versions/3.9.1/lib/python3.9/site-packages/pgcli/pgexecute.py", line 409, in run\n    yield self.execute_normal_sql(sql) + (sql, True, False)\n  File "/home/rpoole/.pyenv/versions/3.9.1/lib/python3.9/site-packages/pgcli/pgexecute.py", line 444, in execute_normal_sql\n    cur.execute(split_sql)\npsycopg2.errors.UniqueViolation: duplicate key value violates unique constraint "minted_play_sale_not_sold"\nDETAIL:  Key (minted_play_id)=(3600) already exists.\n\n'
2021-08-02 15:14:40,000 (15423/MainThread) pgcli.main INFO - Default pager found in config file: "less -SRXF"
2021-08-02 15:14:40,000 (15423/MainThread) pgcli.main WARNING - import keyring failed: ModuleNotFoundError("No module named 'keyring'").
2021-08-08 17:18:07,474 (15423/MainThread) pgcli.pgexecute ERROR - sql: '\\dt', error: OperationalError('server closed the connection unexpectedly\n\tThis probably means the server terminated abnormally\n\tbefore or while processing the request.\n')
2021-08-08 17:18:07,480 (15423/MainThread) pgcli.pgexecute ERROR - traceback: 'Traceback (most recent call last):\n  File "/home/rpoole/.pyenv/versions/3.9.1/lib/python3.9/site-packages/pgcli/pgexecute.py", line 398, in run\n    for result in pgspecial.execute(cur, sql):\n  File "/home/rpoole/.pyenv/versions/3.9.1/lib/python3.9/site-packages/pgspecial/main.py", line 117, in execute\n    return special_cmd.handler(cur=cur, pattern=pattern, verbose=verbose)\n  File "/home/rpoole/.pyenv/versions/3.9.1/lib/python3.9/site-packages/pgspecial/dbcommands.py", line 454, in list_tables\n    return list_objects(cur, pattern, verbose, ["r", "p", ""])\n  File "/home/rpoole/.pyenv/versions/3.9.1/lib/python3.9/site-packages/pgspecial/dbcommands.py", line 445, in list_objects\n    cur.execute(sql)\n  File "/home/rpoole/.pyenv/versions/3.9.1/lib/python3.9/site-packages/pgcli/pgexecute.py", line 39, in _wait_select\n    state = conn.poll()\npsycopg2.OperationalError: server closed the connection unexpectedly\n\tThis probably means the server terminated abnormally\n\tbefore or while processing the request.\n\n'
2021-08-08 17:18:07,480 (15423/MainThread) pgcli.main ERROR - sql: '\\dt', error: OperationalError('server closed the connection unexpectedly\n\tThis probably means the server terminated abnormally\n\tbefore or while processing the request.\n')
2021-08-08 17:18:07,481 (15423/MainThread) pgcli.main ERROR - traceback: 'Traceback (most recent call last):\n  File "/home/rpoole/.pyenv/versions/3.9.1/lib/python3.9/site-packages/pgcli/main.py", line 654, in execute_command\n    output, query = self._evaluate_command(text)\n  File "/home/rpoole/.pyenv/versions/3.9.1/lib/python3.9/site-packages/pgcli/main.py", line 901, in _evaluate_command\n    for title, cur, headers, status, sql, success, is_special in res:\n  File "/home/rpoole/.pyenv/versions/3.9.1/lib/python3.9/site-packages/pgcli/pgexecute.py", line 398, in run\n    for result in pgspecial.execute(cur, sql):\n  File "/home/rpoole/.pyenv/versions/3.9.1/lib/python3.9/site-packages/pgspecial/main.py", line 117, in execute\n    return special_cmd.handler(cur=cur, pattern=pattern, verbose=verbose)\n  File "/home/rpoole/.pyenv/versions/3.9.1/lib/python3.9/site-packages/pgspecial/dbcommands.py", line 454, in list_tables\n    return list_objects(cur, pattern, verbose, ["r", "p", ""])\n  File "/home/rpoole/.pyenv/versions/3.9.1/lib/python3.9/site-packages/pgspecial/dbcommands.py", line 445, in list_objects\n    cur.execute(sql)\n  File "/home/rpoole/.pyenv/versions/3.9.1/lib/python3.9/site-packages/pgcli/pgexecute.py", line 39, in _wait_select\n    state = conn.poll()\npsycopg2.OperationalError: server closed the connection unexpectedly\n\tThis probably means the server terminated abnormally\n\tbefore or while processing the request.\n\n'
2021-08-08 17:40:26,120 (21015/MainThread) pgcli.main INFO - Default pager found in config file: "less -SRXF"
2021-08-08 17:40:26,120 (21015/MainThread) pgcli.main WARNING - import keyring failed: ModuleNotFoundError("No module named 'keyring'").
2021-08-08 17:40:26,154 (21015/MainThread) pgcli.main ERROR - traceback: 'Traceback (most recent call last):\n  File "/home/rpoole/.pyenv/versions/3.9.1/lib/python3.9/site-packages/pgcli/main.py", line 582, in connect\n    raise e\n  File "/home/rpoole/.pyenv/versions/3.9.1/lib/python3.9/site-packages/pgcli/main.py", line 569, in connect\n    pgexecute = PGExecute(database, user, passwd, host, port, dsn, **kwargs)\n  File "/home/rpoole/.pyenv/versions/3.9.1/lib/python3.9/site-packages/pgcli/pgexecute.py", line 214, in __init__\n    self.connect(database, user, password, host, port, dsn, **kwargs)\n  File "/home/rpoole/.pyenv/versions/3.9.1/lib/python3.9/site-packages/pgcli/pgexecute.py", line 254, in connect\n    conn = psycopg2.connect(**conn_params)\n  File "/home/rpoole/.pyenv/versions/3.9.1/lib/python3.9/site-packages/psycopg2/__init__.py", line 122, in connect\n    conn = _connect(dsn, connection_factory=connection_factory, **kwasync)\npsycopg2.OperationalError: could not translate host name "dota-immortals-rds.ccyuyeupbg07.us-east-1.rds.amazonaws.com" to address: No address associated with hostname\n\n'
2021-10-09 00:19:13,861 (25518/MainThread) pgcli.main INFO - Default pager found in config file: "less -SRXF"
2021-10-09 00:19:13,861 (25518/MainThread) pgcli.main WARNING - import keyring failed: ModuleNotFoundError("No module named 'keyring'").
2021-10-09 00:19:13,867 (25518/MainThread) pgcli.main ERROR - traceback: 'Traceback (most recent call last):\n  File "/home/rpoole/.pyenv/versions/3.9.1/lib/python3.9/site-packages/pgcli/main.py", line 582, in connect\n    raise e\n  File "/home/rpoole/.pyenv/versions/3.9.1/lib/python3.9/site-packages/pgcli/main.py", line 569, in connect\n    pgexecute = PGExecute(database, user, passwd, host, port, dsn, **kwargs)\n  File "/home/rpoole/.pyenv/versions/3.9.1/lib/python3.9/site-packages/pgcli/pgexecute.py", line 214, in __init__\n    self.connect(database, user, password, host, port, dsn, **kwargs)\n  File "/home/rpoole/.pyenv/versions/3.9.1/lib/python3.9/site-packages/pgcli/pgexecute.py", line 254, in connect\n    conn = psycopg2.connect(**conn_params)\n  File "/home/rpoole/.pyenv/versions/3.9.1/lib/python3.9/site-packages/psycopg2/__init__.py", line 122, in connect\n    conn = _connect(dsn, connection_factory=connection_factory, **kwasync)\n  File "/home/rpoole/.pyenv/versions/3.9.1/lib/python3.9/site-packages/pgcli/pgexecute.py", line 39, in _wait_select\n    state = conn.poll()\npsycopg2.OperationalError: could not connect to server: Connection refused\n\tIs the server running on host "localhost" (127.0.0.1) and accepting\n\tTCP/IP connections on port 5432?\n\n'
2021-10-09 00:20:13,995 (26214/MainThread) pgcli.main INFO - Default pager found in config file: "less -SRXF"
2021-10-09 00:20:13,995 (26214/MainThread) pgcli.main WARNING - import keyring failed: ModuleNotFoundError("No module named 'keyring'").
2021-10-09 00:20:15,180 (26214/MainThread) pgcli.main ERROR - traceback: 'Traceback (most recent call last):\n  File "/home/rpoole/.pyenv/versions/3.9.1/lib/python3.9/site-packages/pgcli/main.py", line 569, in connect\n    pgexecute = PGExecute(database, user, passwd, host, port, dsn, **kwargs)\n  File "/home/rpoole/.pyenv/versions/3.9.1/lib/python3.9/site-packages/pgcli/pgexecute.py", line 214, in __init__\n    self.connect(database, user, password, host, port, dsn, **kwargs)\n  File "/home/rpoole/.pyenv/versions/3.9.1/lib/python3.9/site-packages/pgcli/pgexecute.py", line 254, in connect\n    conn = psycopg2.connect(**conn_params)\n  File "/home/rpoole/.pyenv/versions/3.9.1/lib/python3.9/site-packages/psycopg2/__init__.py", line 122, in connect\n    conn = _connect(dsn, connection_factory=connection_factory, **kwasync)\n  File "/home/rpoole/.pyenv/versions/3.9.1/lib/python3.9/site-packages/pgcli/pgexecute.py", line 39, in _wait_select\n    state = conn.poll()\npsycopg2.OperationalError: fe_sendauth: no password supplied\n\n\nDuring handling of the above exception, another exception occurred:\n\nTraceback (most recent call last):\n  File "/home/rpoole/.pyenv/versions/3.9.1/lib/python3.9/site-packages/click/termui.py", line 129, in prompt_func\n    return f("")\n  File "/home/rpoole/.pyenv/versions/3.9.1/lib/python3.9/site-packages/click/termui.py", line 54, in hidden_prompt_func\n    return getpass.getpass(prompt)\n  File "/home/rpoole/.pyenv/versions/3.9.1/lib/python3.9/getpass.py", line 77, in unix_getpass\n    passwd = _raw_input(prompt, stream, input=input)\n  File "/home/rpoole/.pyenv/versions/3.9.1/lib/python3.9/getpass.py", line 146, in _raw_input\n    line = input.readline()\nKeyboardInterrupt\n\nDuring handling of the above exception, another exception occurred:\n\nTraceback (most recent call last):\n  File "/home/rpoole/.pyenv/versions/3.9.1/lib/python3.9/site-packages/pgcli/main.py", line 572, in connect\n    passwd = click.prompt(\n  File "/home/rpoole/.pyenv/versions/3.9.1/lib/python3.9/site-packages/click/termui.py", line 147, in prompt\n    value = prompt_func(prompt)\n  File "/home/rpoole/.pyenv/versions/3.9.1/lib/python3.9/site-packages/click/termui.py", line 136, in prompt_func\n    raise Abort()\nclick.exceptions.Abort\n'
2021-10-09 00:20:23,167 (26325/MainThread) pgcli.main INFO - Default pager found in config file: "less -SRXF"
2021-10-09 00:20:23,167 (26325/MainThread) pgcli.main WARNING - import keyring failed: ModuleNotFoundError("No module named 'keyring'").
2021-10-09 00:20:35,197 (26325/MainThread) pgcli.pgexecute ERROR - sql: '\\dl', error: SyntaxError('syntax error at or near "\\"\nLINE 1: \\dl\n        ^\n')
2021-10-09 00:20:35,197 (26325/MainThread) pgcli.pgexecute ERROR - traceback: 'Traceback (most recent call last):\n  File "/home/rpoole/.pyenv/versions/3.9.1/lib/python3.9/site-packages/pgcli/pgexecute.py", line 409, in run\n    yield self.execute_normal_sql(sql) + (sql, True, False)\n  File "/home/rpoole/.pyenv/versions/3.9.1/lib/python3.9/site-packages/pgcli/pgexecute.py", line 444, in execute_normal_sql\n    cur.execute(split_sql)\npsycopg2.errors.SyntaxError: syntax error at or near "\\"\nLINE 1: \\dl\n        ^\n\n'
2021-10-09 09:53:06,539 (1305/MainThread) pgcli.main INFO - Default pager found in config file: "less -SRXF"
2021-10-09 09:53:06,539 (1305/MainThread) pgcli.main WARNING - import keyring failed: ModuleNotFoundError("No module named 'keyring'").
2021-10-09 15:41:06,549 (1758/MainThread) pgcli.main INFO - Default pager found in config file: "less -SRXF"
2021-10-09 15:41:06,550 (1758/MainThread) pgcli.main WARNING - import keyring failed: ModuleNotFoundError("No module named 'keyring'").
2021-10-09 16:15:37,524 (1758/MainThread) pgcli.pgexecute ERROR - sql: '\\d comments', error: OperationalError('server closed the connection unexpectedly\n\tThis probably means the server terminated abnormally\n\tbefore or while processing the request.\n')
2021-10-09 16:15:37,529 (1758/MainThread) pgcli.pgexecute ERROR - traceback: 'Traceback (most recent call last):\n  File "/home/rpoole/.pyenv/versions/3.9.1/lib/python3.9/site-packages/pgcli/pgexecute.py", line 398, in run\n    for result in pgspecial.execute(cur, sql):\n  File "/home/rpoole/.pyenv/versions/3.9.1/lib/python3.9/site-packages/pgspecial/main.py", line 117, in execute\n    return special_cmd.handler(cur=cur, pattern=pattern, verbose=verbose)\n  File "/home/rpoole/.pyenv/versions/3.9.1/lib/python3.9/site-packages/pgspecial/dbcommands.py", line 882, in describe_table_details\n    cur.execute(sql)\n  File "/home/rpoole/.pyenv/versions/3.9.1/lib/python3.9/site-packages/pgcli/pgexecute.py", line 39, in _wait_select\n    state = conn.poll()\npsycopg2.OperationalError: server closed the connection unexpectedly\n\tThis probably means the server terminated abnormally\n\tbefore or while processing the request.\n\n'
2021-10-09 16:15:37,529 (1758/MainThread) pgcli.main ERROR - sql: '\\d comments', error: OperationalError('server closed the connection unexpectedly\n\tThis probably means the server terminated abnormally\n\tbefore or while processing the request.\n')
2021-10-09 16:15:37,529 (1758/MainThread) pgcli.main ERROR - traceback: 'Traceback (most recent call last):\n  File "/home/rpoole/.pyenv/versions/3.9.1/lib/python3.9/site-packages/pgcli/main.py", line 654, in execute_command\n    output, query = self._evaluate_command(text)\n  File "/home/rpoole/.pyenv/versions/3.9.1/lib/python3.9/site-packages/pgcli/main.py", line 901, in _evaluate_command\n    for title, cur, headers, status, sql, success, is_special in res:\n  File "/home/rpoole/.pyenv/versions/3.9.1/lib/python3.9/site-packages/pgcli/pgexecute.py", line 398, in run\n    for result in pgspecial.execute(cur, sql):\n  File "/home/rpoole/.pyenv/versions/3.9.1/lib/python3.9/site-packages/pgspecial/main.py", line 117, in execute\n    return special_cmd.handler(cur=cur, pattern=pattern, verbose=verbose)\n  File "/home/rpoole/.pyenv/versions/3.9.1/lib/python3.9/site-packages/pgspecial/dbcommands.py", line 882, in describe_table_details\n    cur.execute(sql)\n  File "/home/rpoole/.pyenv/versions/3.9.1/lib/python3.9/site-packages/pgcli/pgexecute.py", line 39, in _wait_select\n    state = conn.poll()\npsycopg2.OperationalError: server closed the connection unexpectedly\n\tThis probably means the server terminated abnormally\n\tbefore or while processing the request.\n\n'
2021-10-09 16:18:19,157 (11782/MainThread) pgcli.main INFO - Default pager found in config file: "less -SRXF"
2021-10-09 16:18:19,157 (11782/MainThread) pgcli.main WARNING - import keyring failed: ModuleNotFoundError("No module named 'keyring'").
2021-10-09 16:19:36,167 (1758/MainThread) pgcli.pgexecute ERROR - sql: '\\d comments', error: OperationalError('server closed the connection unexpectedly\n\tThis probably means the server terminated abnormally\n\tbefore or while processing the request.\n')
2021-10-09 16:19:36,167 (1758/MainThread) pgcli.pgexecute ERROR - traceback: 'Traceback (most recent call last):\n  File "/home/rpoole/.pyenv/versions/3.9.1/lib/python3.9/site-packages/pgcli/pgexecute.py", line 398, in run\n    for result in pgspecial.execute(cur, sql):\n  File "/home/rpoole/.pyenv/versions/3.9.1/lib/python3.9/site-packages/pgspecial/main.py", line 117, in execute\n    return special_cmd.handler(cur=cur, pattern=pattern, verbose=verbose)\n  File "/home/rpoole/.pyenv/versions/3.9.1/lib/python3.9/site-packages/pgspecial/dbcommands.py", line 882, in describe_table_details\n    cur.execute(sql)\n  File "/home/rpoole/.pyenv/versions/3.9.1/lib/python3.9/site-packages/pgcli/pgexecute.py", line 39, in _wait_select\n    state = conn.poll()\npsycopg2.OperationalError: server closed the connection unexpectedly\n\tThis probably means the server terminated abnormally\n\tbefore or while processing the request.\n\n'
2021-10-09 16:19:36,167 (1758/MainThread) pgcli.main ERROR - sql: '\\d comments', error: OperationalError('server closed the connection unexpectedly\n\tThis probably means the server terminated abnormally\n\tbefore or while processing the request.\n')
2021-10-09 16:19:36,167 (1758/MainThread) pgcli.main ERROR - traceback: 'Traceback (most recent call last):\n  File "/home/rpoole/.pyenv/versions/3.9.1/lib/python3.9/site-packages/pgcli/main.py", line 654, in execute_command\n    output, query = self._evaluate_command(text)\n  File "/home/rpoole/.pyenv/versions/3.9.1/lib/python3.9/site-packages/pgcli/main.py", line 901, in _evaluate_command\n    for title, cur, headers, status, sql, success, is_special in res:\n  File "/home/rpoole/.pyenv/versions/3.9.1/lib/python3.9/site-packages/pgcli/pgexecute.py", line 398, in run\n    for result in pgspecial.execute(cur, sql):\n  File "/home/rpoole/.pyenv/versions/3.9.1/lib/python3.9/site-packages/pgspecial/main.py", line 117, in execute\n    return special_cmd.handler(cur=cur, pattern=pattern, verbose=verbose)\n  File "/home/rpoole/.pyenv/versions/3.9.1/lib/python3.9/site-packages/pgspecial/dbcommands.py", line 882, in describe_table_details\n    cur.execute(sql)\n  File "/home/rpoole/.pyenv/versions/3.9.1/lib/python3.9/site-packages/pgcli/pgexecute.py", line 39, in _wait_select\n    state = conn.poll()\npsycopg2.OperationalError: server closed the connection unexpectedly\n\tThis probably means the server terminated abnormally\n\tbefore or while processing the request.\n\n'
2021-10-10 12:19:43,579 (13262/MainThread) pgcli.main INFO - Default pager found in config file: "less -SRXF"
2021-10-10 12:19:43,580 (13262/MainThread) pgcli.main WARNING - import keyring failed: ModuleNotFoundError("No module named 'keyring'").
